Workbook

Sheet Referans
B2: DURUM | C2: SÜREÇ SAHİBİ | D2: PROJE ADI | E2: İHALE NO
B3: PROJELENDİRME | C3: DİZAYN OFİS | D3: 3025 - ORION | E3: 01.17.00 HİDROLİK DAĞITICI & SABİT POMPA
B4: TALEP AŞAMASINDA | C4: ŞANTİYE | D4: 3026 - ORION II | E4: 01.17.01 KULE VİNÇ KİRALAMA & SERVİS
B5: HAZIRLIK AŞAMASINDA | C5: İHALE VE SATINALMA | D5: 3028 - MONA | E5: 01.17.02 PERSONEL ASANSÖRÜ
B6: İHALE AŞAMASINDA | C6: YÖNETİM | D6: 3036 - DİKİLİ ARSA | E6: 01.17.04 MOBİL VİNÇ TEMİNİ
B7: DEĞERLENDİRME | C7: HUKUK | E7: 01.17.05 KULE VİNÇ BAĞLANTI KOLLARI
B8: SÖZLEŞME | E8: 01.18.00 OSGB İŞLERİ
B9: İPTAL | E9: 01.18.01 GÜVENLİK AĞI TEMİN VE MONTAJ İMALATLARI
B10: TAMAMLANDI | E10: 01.18.02 İŞ GÜVENLİĞİ BARİYERİ
E11: 01.19.00 RÜZGAR PERDESİ KALIP KİRALAMA
E12: 05.03.00 ZEMİN ETÜDÜ
E13: 07.01.00 MOBİLİZASYON İŞLERİ
E14: 09.01.00 YIKIM İŞLERİ
E15: 09.02.00 HAFRİYAT
E16: 11.00.00 KAZIK BAŞI KIRIM İŞLERİ
E17: 11.00.00 (M) DÖKME ÇİMENTO MALZEME
E18: 11.01.00 İKSA İŞLERİ
E19: 11.02.00 ZEMİN İYİLEŞTİRME
E20: 11.03.00 ZEMİN İYİLEŞTİRME TEST YAPILMASI
E21: 13.01.00 KABA YAPI İŞLERİ
E22: 13.01.00 (M) HAZIR BETON MALZEME
... E144: 35.01.00 ASANSÖR İŞLERİ

Sheet Şablon
E1: 1 | F1: 2 | G1: 3 | H1: 4 | I1: 5 | J1: 6 | K1: 7 | L1: 8 | M1: 9 | N1: 10 | O1: 11 | P1: 12 | Q1: 13
B2: PROJE KODU | C2: SIRA NO | D2: ETAP | E2: İHALE NO | F2: İHALE KODU | G2: İHALE KATEGORİ | H2: İHALE BÖLÜMÜ | I2: DİZAYN PROJE YAYINLAMA SÜRESİ | J2: TALEP HAZIRLIK SÜRESİ | K2: İHALE HAZIRLIK SÜRESİ (MSA) | L2: İHALE SÜRESİ | M2: İHALE KARAR SÜRESİ | N2: AVANS + SÖZLEŞME SÜRESİ | O2: PROJELENDİRME / NUMUNE ONAY SÜRESİ | P2: ÜRETİM / TERMİN / MOBİLİZAYON SÜRESİ | Q2: NOT
B3: ='Satınalma Takvimi Veri Girişi'!$B$1 -> 3028 - MONA | C3: 001 | D3: 1 | E3: =CONCATENATE("IHL.",LEFT(B3,4),".",C3,"/",D3) -> IHL.3028.001/1 | F3: 09.01.00 YIKIM İŞLERİ | G3: B KATEGORİ | H3: İNŞ | I3: 0 | J3: 14 | K3: 7 | L3: 14 | M3: 7 | N3: 7 | O3: 0 | P3: 7
B4: ='Satınalma Takvimi Veri Girişi'!$B$1 -> 3028 - MONA | C4: 002 | D4: 1 | E4: =CONCATENATE("IHL.",LEFT(B4,4),".",C4,"/",D4) -> IHL.3028.002/1 | F4: 05.03.00 ZEMİN ETÜDÜ | G4: C KATEGORİ | H4: İNŞ | I4: 0 | J4: 14 | K4: 7 | L4: 14 | M4: 7 | N4: 7 | O4: 0 | P4: 7
B5: ='Satınalma Takvimi Veri Girişi'!$B$1 -> 3028 - MONA | C5: 003 | D5: 1 | E5: =CONCATENATE("IHL.",LEFT(B5,4),".",C5,"/",D5) -> IHL.3028.003/1 | F5: 01.18.00 OSGB İŞLERİ | G5: C KATEGORİ | H5: İNŞ | I5: 0 | J5: 14 | K5: 7 | L5: 14 | M5: 7 | N5: 7 | O5: 0 | P5: 7
B6: ='Satınalma Takvimi Veri Girişi'!$B$1 -> 3028 - MONA | C6: 004 | D6: 1 | E6: =CONCATENATE("IHL.",LEFT(B6,4),".",C6,"/",D6) -> IHL.3028.004/1 | F6: 07.01.00 MOBİLİZASYON İŞLERİ | G6: C KATEGORİ | H6: İNŞ | I6: 0 | J6: 14 | K6: 7 | L6: 28 | M6: 7 | N6: 14 | O6: 7 | P6: 28
B7: ='Satınalma Takvimi Veri Girişi'!$B$1 -> 3028 - MONA | C7: 005 | D7: 1 | E7: =CONCATENATE("IHL.",LEFT(B7,4),".",C7,"/",D7) -> IHL.3028.005/1 | F7: 11.03.00 ZEMİN İYİLEŞTİRME TEST YAPILMASI | G7: C KATEGORİ | H7: İNŞ | J7: 14 | K7: 7 | L7: 28 | M7: 7 | N7: 14 | O7: 0 | P7: 28
B8: ='Satınalma Takvimi Veri Girişi'!$B$1 -> 3028 - MONA | C8: 006 | D8: 1 | E8: =CONCATENATE("IHL.",LEFT(B8,4),".",C8,"/",D8) -> IHL.3028.006/1 | F8: 11.01.00 İKSA İŞLERİ | G8: A KATEGORİ | H8: İNŞ | J8: 14 | K8: 14 | L8: 28 | M8: 10 | N8: 14 | O8: 0 | P8: 14
B9: ='Satınalma Takvimi Veri Girişi'!$B$1 -> 3028 - MONA | C9: 007 | D9: 1 | E9: =CONCATENATE("IHL.",LEFT(B9,4),".",C9,"/",D9) -> IHL.3028.007/1 | F9: 11.00.00 (M) DÖKME ÇİMENTO MALZEME | G9: B KATEGORİ | H9: İNŞ | I9: 0 | J9: 14 | K9: 7 | L9: 21 | M9: 7 | N9: 14 | O9: 0 | P9: 7
B10: ='Satınalma Takvimi Veri Girişi'!$B$1 -> 3028 - MONA | C10: 008 | D10: 1 | E10: =CONCATENATE("IHL.",LEFT(B10,4),".",C10,"/",D10) -> IHL.3028.008/1 | F10: 13.01.00 (M) HAZIR BETON MALZEME | G10: B KATEGORİ | H10: İNŞ | I10: 0 | J10: 14 | K10: 7 | L10: 21 | M10: 7 | N10: 14 | O10: 0 | P10: 7
B11: ='Satınalma Takvimi Veri Girişi'!$B$1 -> 3028 - MONA | C11: 009 | D11: 1 | E11: =CONCATENATE("IHL.",LEFT(B11,4),".",C11,"/",D11) -> IHL.3028.009/1 | F11: 09.02.00 HAFRİYAT | G11: A KATEGORİ | H11: İNŞ | J11: 14 | K11: 14 | L11: 28 | M11: 10 | N11: 14 | O11: 0 | P11: 7
B12: ='Satınalma Takvimi Veri Girişi'!$B$1 -> 3028 - MONA | C12: 010 | D12: 1 | E12: =CONCATENATE("IHL.",LEFT(B12,4),".",C12,"/",D12) -> IHL.3028.010/1 | F12: 11.02.00 ZEMİN İYİLEŞTİRME | G12: A KATEGORİ | H12: İNŞ | J12: 14 | K12: 14 | L12: 28 | M12: 10 | N12: 14 | O12: 0 | P12: 14
B13: ='Satınalma Takvimi Veri Girişi'!$B$1 -> 3028 - MONA | C13: 011 | D13: 1 | E13: =CONCATENATE("IHL.",LEFT(B13,4),".",C13,"/",D13) -> IHL.3028.011/1 | F13: 11.00.00 KAZIK BAŞI KIRIM İŞLERİ | G13: B KATEGORİ | H13: İNŞ | I13: 0 | J13: 14 | K13: 7 | L13: 14 | M13: 7 | N13: 7 | O13: 0 | P13: 7
B14: ='Satınalma Takvimi Veri Girişi'!$B$1 -> 3028 - MONA | C14: 012 | D14: 1 | E14: =CONCATENATE("IHL.",LEFT(B14,4),".",C14,"/",D14) -> IHL.3028.012/1 | F14: 23.01.00 TEMEL ALTI YALITIM | G14: A KATEGORİ | H14: İNŞ | J14: 14 | K14: 14 | L14: 28 | M14: 10 | N14: 21 | O14: 7 | P14: 7
B15: ='Satınalma Takvimi Veri Girişi'!$B$1 -> 3028 - MONA | C15: 013 | D15: 1 | E15: =CONCATENATE("IHL.",LEFT(B15,4),".",C15,"/",D15) -> IHL.3028.013/1 | F15: 01.17.04 MOBİL VİNÇ TEMİNİ | G15: B KATEGORİ | H15: İNŞ | I15: 0 | J15: 14 | K15: 7 | L15: 7 | M15: 7 | N15: 7 | O15: 0 | P15: 7
B16: ='Satınalma Takvimi Veri Girişi'!$B$1 -> 3028 - MONA | C16: 014 | D16: 1 | E16: =CONCATENATE("IHL.",LEFT(B16,4),".",C16,"/",D16) -> IHL.3028.014/1 | F16: 13.01.00 KABA YAPI İŞLERİ | G16: A KATEGORİ | H16: İNŞ | J16: 21 | K16: 21 | L16: 45 | M16: 10 | N16: 21 | O16: 0 | P16: 14
B17: ='Satınalma Takvimi Veri Girişi'!$B$1 -> 3028 - MONA | C17: 015 | D17: 1 | E17: =CONCATENATE("IHL.",LEFT(B17,4),".",C17,"/",D17) -> IHL.3028.015/1 | F17: 13.02.01 ÇELİK ANKRAJ PLAKA İŞLERİ | G17: B KATEGORİ | H17: İNŞ | J17: 14 | K17: 7 | L17: 7 | M17: 7 | N17: 7 | O17: 7 | P17: 7
B18: ='Satınalma Takvimi Veri Girişi'!$B$1 -> 3028 - MONA | C18: 016 | D18: 1 | E18: =CONCATENATE("IHL.",LEFT(B18,4),".",C18,"/",D18) -> IHL.3028.016/1 | F18: 01.17.01 KULE VİNÇ KİRALAMA & SERVİS | G18: B KATEGORİ | H18: İNŞ | I18: 0 | J18: 14 | K18: 7 | L18: 21 | M18: 7 | N18: 7 | O18: 0 | P18: 14
B19: ='Satınalma Takvimi Veri Girişi'!$B$1 -> 3028 - MONA | C19: 017 | D19: 1 | E19: =CONCATENATE("IHL.",LEFT(B19,4),".",C19,"/",D19) -> IHL.3028.017/1 | F19: 01.18.01 GÜVENLİK AĞI TEMİN VE MONTAJ İMALATLARI | G19: B KATEGORİ | H19: İNŞ | I19: 0 | J19: 14 | K19: 7 | L19: 14 | M19: 7 | N19: 7 | O19: 0 | P19: 14
B20: ='Satınalma Takvimi Veri Girişi'!$B$1 -> 3028 - MONA | C20: 018 | D20: 1 | E20: =CONCATENATE("IHL.",LEFT(B20,4),".",C20,"/",D20) -> IHL.3028.018/1 | F20: 01.18.02 İŞ GÜVENLİĞİ BARİYERİ | G20: B KATEGORİ | H20: İNŞ | I20: 0 | J20: 14 | K20: 7 | L20: 14 | M20: 7 | N20: 7 | O20: 0 | P20: 14
B21: ='Satınalma Takvimi Veri Girişi'!$B$1 -> 3028 - MONA | C21: 019 | D21: 1 | E21: =CONCATENATE("IHL.",LEFT(B21,4),".",C21,"/",D21) -> IHL.3028.019/1 | F21: 01.19.00 RÜZGAR PERDESİ KALIP KİRALAMA | G21: B KATEGORİ | H21: İNŞ | J21: 14 | K21: 7 | L21: 21 | M21: 7 | N21: 14 | O21: 7 | P21: 28
B22: ='Satınalma Takvimi Veri Girişi'!$B$1 -> 3028 - MONA | C22: 020 | D22: 1 | E22: =CONCATENATE("IHL.",LEFT(B22,4),".",C22,"/",D22) -> IHL.3028.020/1 | F22: 15.15.02 RCS ÜZERİ LOGO İŞLERİ | G22: C KATEGORİ | H22: İNŞ | J22: 14 | K22: 7 | L22: 14 | M22: 7 | N22: 7 | O22: 7 | P22: 14
B23: ='Satınalma Takvimi Veri Girişi'!$B$1 -> 3028 - MONA | C23: 021 | D23: 1 | E23: =CONCATENATE("IHL.",LEFT(B23,4),".",C23,"/",D23) -> IHL.3028.021/1 | F23: 01.17.02 PERSONEL ASANSÖRÜ | G23: B KATEGORİ | H23: İNŞ | I23: 0 | J23: 14 | K23: 7 | L23: 21 | M23: 7 | N23: 7 | O23: 7 | P23: 28
B24: ='Satınalma Takvimi Veri Girişi'!$B$1 -> 3028 - MONA | C24: 022 | D24: 1 | E24: =CONCATENATE("IHL.",LEFT(B24,4),".",C24,"/",D24) -> IHL.3028.022/1 | F24: 01.17.00 HİDROLİK DAĞITICI & SABİT POMPA | G24: B KATEGORİ | H24: İNŞ | I24: 0 | J24: 14 | K24: 7 | L24: 21 | M24: 7 | N24: 7 | O24: 7 | P24: 14
B25: ='Satınalma Takvimi Veri Girişi'!$B$1 -> 3028 - MONA | C25: 023 | D25: 1 | E25: =CONCATENATE("IHL.",LEFT(B25,4),".",C25,"/",D25) -> IHL.3028.023/1 | F25: 19.02.00 ALÜMİNYUM DOĞRAMA VE CEPHE KAPLAMA | G25: A KATEGORİ | H25: İNŞ | J25: 30 | K25: 21 | L25: 60 | M25: 10 | N25: 21 | O25: 28 | P25: 14
B26: ='Satınalma Takvimi Veri Girişi'!$B$1 -> 3028 - MONA | C26: 024 | D26: 1 | E26: =CONCATENATE("IHL.",LEFT(B26,4),".",C26,"/",D26) -> IHL.3028.024/1 | F26: 19.03.00 PREKAST CEPHE KAPLAMA | G26: A KATEGORİ | H26: İNŞ | J26: 30 | K26: 21 | L26: 60 | M26: 10 | N26: 21 | O26: 28 | P26: 45
B27: ='Satınalma Takvimi Veri Girişi'!$B$1 -> 3028 - MONA | C27: 025 | D27: 1 | E27: =CONCATENATE("IHL.",LEFT(B27,4),".",C27,"/",D27) -> IHL.3028.025/1 | F27: 19.03.01 DOĞALTAŞ CEPHE KAPLAMA İŞLERİ | G27: A KATEGORİ | H27: İNŞ | J27: 14 | K27: 21 | L27: 45 | M27: 10 | N27: 21 | O27: 28 | P27: 28
B28: ='Satınalma Takvimi Veri Girişi'!$B$1 -> 3028 - MONA | C28: 026 | D28: 1 | E28: =CONCATENATE("IHL.",LEFT(B28,4),".",C28,"/",D28) -> IHL.3028.026/1 | F28: 19.03.02 THERMOWOOD CEPHE KAPLAMA İŞLERİ | G28: A KATEGORİ | H28: İNŞ | J28: 14 | K28: 14 | L28: 28 | M28: 10 | N28: 14 | O28: 14 | P28: 28
B29: ='Satınalma Takvimi Veri Girişi'!$B$1 -> 3028 - MONA | C29: 027 | D29: 1 | E29: =CONCATENATE("IHL.",LEFT(B29,4),".",C29,"/",D29) -> IHL.3028.027/1 | F29: 19.03.03 FIBERCEMENT CEPHE KAPLAMA İŞLERİ | G29: A KATEGORİ | H29: İNŞ | J29: 14 | K29: 14 | L29: 28 | M29: 10 | N29: 14 | O29: 14 | P29: 28
B30: ='Satınalma Takvimi Veri Girişi'!$B$1 -> 3028 - MONA | C30: 028 | D30: 1 | E30: =CONCATENATE("IHL.",LEFT(B30,4),".",C30,"/",D30) -> IHL.3028.028/1 | F30: 19.01.01 DIŞ CEPHE SIVA & BOYA İŞLERİ | G30: A KATEGORİ | H30: İNŞ | J30: 14 | K30: 7 | L30: 28 | M30: 10 | N30: 14 | O30: 0 | P30: 7
B31: ='Satınalma Takvimi Veri Girişi'!$B$1 -> 3028 - MONA | C31: 029 | D31: 1 | E31: =CONCATENATE("IHL.",LEFT(B31,4),".",C31,"/",D31) -> IHL.3028.029/1 | F31: 19.01.00 DIŞ CEPHE MANTOLAMA İŞLERİ | G31: A KATEGORİ | H31: İNŞ | J31: 14 | K31: 14 | L31: 28 | M31: 10 | N31: 14 | O31: 7 | P31: 7
B32: ='Satınalma Takvimi Veri Girişi'!$B$1 -> 3028 - MONA | C32: 030 | D32: 1 | E32: =CONCATENATE("IHL.",LEFT(B32,4),".",C32,"/",D32) -> IHL.3028.030/1 | F32: 15.12.00 KİREMİT ÇATI İŞLERİ | G32: A KATEGORİ | H32: İNŞ | J32: 14 | K32: 14 | L32: 28 | M32: 10 | N32: 14 | O32: 7 | P32: 14
B33: ='Satınalma Takvimi Veri Girişi'!$B$1 -> 3028 - MONA | C33: 031 | D33: 1 | E33: =CONCATENATE("IHL.",LEFT(B33,4),".",C33,"/",D33) -> IHL.3028.031/1 | F33: 15.12.01 KENET ÇATI İŞLERİ | G33: A KATEGORİ | H33: İNŞ | J33: 14 | K33: 14 | L33: 28 | M33: 10 | N33: 14 | O33: 7 | P33: 14
B34: ='Satınalma Takvimi Veri Girişi'!$B$1 -> 3028 - MONA | C34: 032 | D34: 1 | E34: =CONCATENATE("IHL.",LEFT(B34,4),".",C34,"/",D34) -> IHL.3028.032/1 | F34: 19.03.04 CAM SAÇAK KAPLAMA İŞLERİ | G34: B KATEGORİ | H34: İNŞ | J34: 14 | K34: 14 | L34: 28 | M34: 7 | N34: 21 | O34: 7 | P34: 60
B35: ='Satınalma Takvimi Veri Girişi'!$B$1 -> 3028 - MONA | C35: 033 | D35: 1 | E35: =CONCATENATE("IHL.",LEFT(B35,4),".",C35,"/",D35) -> IHL.3028.033/1 | F35: 19.03.05 ALÜMİNYUM SAÇAK KAPLAMA İŞLERİ | G35: B KATEGORİ | H35: İNŞ | J35: 14 | K35: 14 | L35: 28 | M35: 7 | N35: 21 | O35: 7 | P35: 60
B36: ='Satınalma Takvimi Veri Girişi'!$B$1 -> 3028 - MONA | C36: 034 | D36: 1 | E36: =CONCATENATE("IHL.",LEFT(B36,4),".",C36,"/",D36) -> IHL.3028.034/1 | F36: 19.06.00 PANJUR İŞLERİ | G36: B KATEGORİ | H36: İNŞ | J36: 14 | K36: 14 | L36: 28 | M36: 7 | N36: 14 | O36: 7 | P36: 60
... B47: ='Satınalma Takvimi Veri Girişi'!$B$1 -> 3028 - MONA | C47: 042 | D47: 1 | E47: =CONCATENATE("IHL.",LEFT(B47,4),".",C47,"/",D47) -> IHL.3028.042/1 | F47: 15.02.00 ALÇI LEVHA, SIVA & BOYA İŞLERİ | G47: A KATEGORİ | H47: İNŞ | J47: 14 | K47: 14 | L47: 28 | M47: 10 | N47: 14 | O47: 0 | P47: 14
B48: ='Satınalma Takvimi Veri Girişi'!$B$1 -> 3028 - MONA | C48: 043 | D48: 1 | E48: =CONCATENATE("IHL.",LEFT(B48,4),".",C48,"/",D48) -> IHL.3028.043/1 | F48: 01.17.05 KULE VİNÇ BAĞLANTI KOLLARI | G48: C KATEGORİ | H48: İNŞ | I48: 0 | J48: 14 | K48: 7 | L48: 14 | M48: 7 | N48: 7 | O48: 7 | P48: 28
B49: ='Satınalma Takvimi Veri Girişi'!$B$1 -> 3028 - MONA | C49: 044 | D49: 1 | E49: =CONCATENATE("IHL.",LEFT(B49,4),".",C49,"/",D49) -> IHL.3028.044/1 | F49: 23.01.01 ISLAK HACİM YALITIM | G49: A KATEGORİ | H49: İNŞ | J49: 14 | K49: 14 | L49: 21 | M49: 10 | N49: 14 | O49: 7 | P49: 7
B50: ='Satınalma Takvimi Veri Girişi'!$B$1 -> 3028 - MONA | C50: 045 | D50: 1 | E50: =CONCATENATE("IHL.",LEFT(B50,4),".",C50,"/",D50) -> IHL.3028.045/1 | F50: 23.01.02 BALKON & TERAS YALITIM | G50: A KATEGORİ | H50: İNŞ | J50: 14 | K50: 14 | L50: 21 | M50: 10 | N50: 14 | O50: 7 | P50: 7
...

Sheet Kullanım Klavuzu
B2: KULLANIM KLAVUZU
B3: 1 | C3: Proje kodu çoktan seçmeli olarak B1 hücresinden seçilmelidir
B4: =+B3+1 -> 2 | C4: Yeni proje kodu admin tarafından açılmaktadır, yeni proje eklenmesi gerekirse admine bilgi veriniz.
B5: =+B4+1 -> 3 | C5: Tablo ilk kez oluşturulurken şablonda yer alan planlanan süreler kontrol edilmeli ve gerekmesi halinde admine bilgi verilerek güncellenmelidir.
B6: =+B5+1 -> 4 | C6: ihale kodu ve ihale numarası değştirilmemelidir.
B7: =+B6+1 -> 5 | C7: Aynı ihale kodundan birden fazla ihale olacaksa (merdiven çelik, pergole çelik veya villa kaba yapı, residance kaba yapı gibi) etap kısmı 2,3,4 şeklinde olacak şekilde satır eklenmelidir.
B8: =+B7+1 -> 6 | C8: Aynı ihale kodundan birden fazla ihale olacaksa veya listede olmayan yeni ihale numarası eklenecekse bu ekleme admin tarafından yapılmalıdır.
B9: =+B8+1 -> 7 | C9: Şablonda olup kullanılmayacak olan ihalelere ilişkin satır silinmelidir.
B10: =+B9+1 -> 8 | C10: Her ihalenin ihale kodu farklı olmalı, eğer aynı kod olursa hücre rengi kırmızı olarak uyarı vermekte
B11: =+B10+1 -> 9 | C11: Raporun doğru çalışması için iş şablon bir kez sisteme yüklenmeli ve sonrasında rapor ekranında yer alan planlanan imalat başlangıç tarihi sisteme eklenmelidir.
B12: =+B11+1 -> 10 | C12: Raporun çalışması için Veri girişindeki B1 hücresinde yer alan proje kodu ve U sütununda yer alan planlanan başlangıç tarihi kesinlikle girilmelidir.
B13: =+B12+1 -> 11 | C13: Raporun proje boyunca sağlıklı takip edilebilmesi için gerçekleşen tarihler, SAT, SAS noları ve anlaşma tutarları yazılmalıdır.

Sheet Satınalma Takvimi Veri Girişi
B1: 3028 - MONA
B2: İHALE NO | C2: İHALE KODU | D2: İHALE ADI / AÇIKLAMA | E2: İHALE KATEGORİ | F2: İHALE BÖLÜMÜ | G2: TASARIM KARARLARININ VERİLMESİ | I2: PROJE YAYIN TARİHİ | K2: TALEP (SAT) TARİHİ | M2: İHALE YAYINI | O2: YÖNETİME SUNUM TARİHİ | Q2: İHALE KARAR TARİHİ | S2: SÖZLEŞME İMZA TARİHİ | U2: İMALAT BAŞLANGIÇ TARİHİ | W2: SAT NO | X2: FİRMA ADI | Y2: SAS NO | Z2: SÖZLEŞME TUTARI TL | AA2: SÖZLEŞME TUTARI USD | AB2: SÖZLEŞME TUTARI EURO | AC2: DİZAYN İLERLEME YÜZDESİ
G3: PLANLANAN | H3: GERÇEKLEŞEN | I3: PLANLANAN | J3: GERÇEKLEŞEN | K3: PLANLANAN | L3: GERÇEKLEŞEN | M3: PLANLANAN | N3: GERÇEKLEŞEN | O3: PLANLANAN | P3: GERÇEKLEŞEN | Q3: PLANLANAN | R3: GERÇEKLEŞEN | S3: PLANLANAN | T3: GERÇEKLEŞEN | U3: PLANLANAN | V3: GERÇEKLEŞEN
B4: =Şablon!E3 -> IHL.3028.001/1 | C4: =VLOOKUP($B4,Şablon!$E$3:$Q$255,2,FALSE) -> 09.01.00 YIKIM İŞLERİ | E4: =VLOOKUP($B4,Şablon!$E$3:$Q$255,3,FALSE) -> B KATEGORİ | F4: =VLOOKUP($B4,Şablon!$E$3:$Q$255,4,FALSE) -> İNŞ | G4: =I4-VLOOKUP($B4,Şablon!$E$3:$Q$255,5,FALSE) -> -56 | I4: =K4-VLOOKUP($B4,Şablon!$E$3:$Q$255,6,FALSE) -> -56 | K4: =M4-VLOOKUP($B4,Şablon!$E$3:$Q$255,7,FALSE) -> -42 | M4: =O4-VLOOKUP($B4,Şablon!$E$3:$Q$255,8,FALSE) -> -35 | O4: =Q4-VLOOKUP($B4,Şablon!$E$3:$Q$255,9,FALSE) -> -21 | Q4: =S4-VLOOKUP($B4,Şablon!$E$3:$Q$255,10,FALSE) -> -14 | S4: =U4-(VLOOKUP($B4,Şablon!$E$3:$Q$255,11,FALSE)+VLOOKUP($B4,Şablon!$E$3:$Q$255,12,FALSE)) -> -7
B5: =Şablon!E4 -> IHL.3028.002/1 | C5: =VLOOKUP($B5,Şablon!$E$3:$Q$255,2,FALSE) -> 05.03.00 ZEMİN ETÜDÜ | E5: =VLOOKUP($B5,Şablon!$E$3:$Q$255,3,FALSE) -> C KATEGORİ | F5: =VLOOKUP($B5,Şablon!$E$3:$Q$255,4,FALSE) -> İNŞ | G5: =I5-VLOOKUP($B5,Şablon!$E$3:$Q$255,5,FALSE) -> -56 | I5: =K5-VLOOKUP($B5,Şablon!$E$3:$Q$255,6,FALSE) -> -56 | K5: =M5-VLOOKUP($B5,Şablon!$E$3:$Q$255,7,FALSE) -> -42 | M5: =O5-VLOOKUP($B5,Şablon!$E$3:$Q$255,8,FALSE) -> -35 | O5: =Q5-VLOOKUP($B5,Şablon!$E$3:$Q$255,9,FALSE) -> -21 | Q5: =S5-VLOOKUP($B5,Şablon!$E$3:$Q$255,10,FALSE) -> -14 | S5: =U5-(VLOOKUP($B5,Şablon!$E$3:$Q$255,11,FALSE)+VLOOKUP($B5,Şablon!$E$3:$Q$255,12,FALSE)) -> -7
B6: =Şablon!E5 -> IHL.3028.003/1 | C6: =VLOOKUP($B6,Şablon!$E$3:$Q$255,2,FALSE) -> 01.18.00 OSGB İŞLERİ | E6: =VLOOKUP($B6,Şablon!$E$3:$Q$255,3,FALSE) -> C KATEGORİ | F6: =VLOOKUP($B6,Şablon!$E$3:$Q$255,4,FALSE) -> İNŞ | G6: =I6-VLOOKUP($B6,Şablon!$E$3:$Q$255,5,FALSE) -> -56 | I6: =K6-VLOOKUP($B6,Şablon!$E$3:$Q$255,6,FALSE) -> -56 | K6: =M6-VLOOKUP($B6,Şablon!$E$3:$Q$255,7,FALSE) -> -42 | M6: =O6-VLOOKUP($B6,Şablon!$E$3:$Q$255,8,FALSE) -> -35 | O6: =Q6-VLOOKUP($B6,Şablon!$E$3:$Q$255,9,FALSE) -> -21 | Q6: =S6-VLOOKUP($B6,Şablon!$E$3:$Q$255,10,FALSE) -> -14 | S6: =U6-(VLOOKUP($B6,Şablon!$E$3:$Q$255,11,FALSE)+VLOOKUP($B6,Şablon!$E$3:$Q$255,12,FALSE)) -> -7
B7: =Şablon!E6 -> IHL.3028.004/1 | C7: =VLOOKUP($B7,Şablon!$E$3:$Q$255,2,FALSE) -> 07.01.00 MOBİLİZASYON İŞLERİ | E7: =VLOOKUP($B7,Şablon!$E$3:$Q$255,3,FALSE) -> C KATEGORİ | F7: =VLOOKUP($B7,Şablon!$E$3:$Q$255,4,FALSE) -> İNŞ | G7: =I7-VLOOKUP($B7,Şablon!$E$3:$Q$255,5,FALSE) -> -105 | I7: =K7-VLOOKUP($B7,Şablon!$E$3:$Q$255,6,FALSE) -> -105 | K7: =M7-VLOOKUP($B7,Şablon!$E$3:$Q$255,7,FALSE) -> -91 | M7: =O7-VLOOKUP($B7,Şablon!$E$3:$Q$255,8,FALSE) -> -84 | O7: =Q7-VLOOKUP($B7,Şablon!$E$3:$Q$255,9,FALSE) -> -56 | Q7: =S7-VLOOKUP($B7,Şablon!$E$3:$Q$255,10,FALSE) -> -49 | S7: =U7-(VLOOKUP($B7,Şablon!$E$3:$Q$255,11,FALSE)+VLOOKUP($B7,Şablon!$E$3:$Q$255,12,FALSE)) -> -35
B8: =Şablon!E7 -> IHL.3028.005/1 | C8: =VLOOKUP($B8,Şablon!$E$3:$Q$255,2,FALSE) -> 11.03.00 ZEMİN İYİLEŞTİRME TEST YAPILMASI | E8: =VLOOKUP($B8,Şablon!$E$3:$Q$255,3,FALSE) -> C KATEGORİ | F8: =VLOOKUP($B8,Şablon!$E$3:$Q$255,4,FALSE) -> İNŞ | G8: =I8-VLOOKUP($B8,Şablon!$E$3:$Q$255,5,FALSE) -> -98 | I8: =K8-VLOOKUP($B8,Şablon!$E$3:$Q$255,6,FALSE) -> -98 | K8: =M8-VLOOKUP($B8,Şablon!$E$3:$Q$255,7,FALSE) -> -84 | M8: =O8-VLOOKUP($B8,Şablon!$E$3:$Q$255,8,FALSE) -> -77 | O8: =Q8-VLOOKUP($B8,Şablon!$E$3:$Q$255,9,FALSE) -> -49 | Q8: =S8-VLOOKUP($B8,Şablon!$E$3:$Q$255,10,FALSE) -> -42 | S8: =U8-(VLOOKUP($B8,Şablon!$E$3:$Q$255,11,FALSE)+VLOOKUP($B8,Şablon!$E$3:$Q$255,12,FALSE)) -> -28
B9: =Şablon!E8 -> IHL.3028.006/1 | C9: =VLOOKUP($B9,Şablon!$E$3:$Q$255,2,FALSE) -> 11.01.00 İKSA İŞLERİ | E9: =VLOOKUP($B9,Şablon!$E$3:$Q$255,3,FALSE) -> A KATEGORİ | F9: =VLOOKUP($B9,Şablon!$E$3:$Q$255,4,FALSE) -> İNŞ | G9: =I9-VLOOKUP($B9,Şablon!$E$3:$Q$255,5,FALSE) -> -94 | I9: =K9-VLOOKUP($B9,Şablon!$E$3:$Q$255,6,FALSE) -> -94 | K9: =M9-VLOOKUP($B9,Şablon!$E$3:$Q$255,7,FALSE) -> -80 | M9: =O9-VLOOKUP($B9,Şablon!$E$3:$Q$255,8,FALSE) -> -66 | O9: =Q9-VLOOKUP($B9,Şablon!$E$3:$Q$255,9,FALSE) -> -38 | Q9: =S9-VLOOKUP($B9,Şablon!$E$3:$Q$255,10,FALSE) -> -28 | S9: =U9-(VLOOKUP($B9,Şablon!$E$3:$Q$255,11,FALSE)+VLOOKUP($B9,Şablon!$E$3:$Q$255,12,FALSE)) -> -14
B10: =Şablon!E9 -> IHL.3028.007/1 | C10: =VLOOKUP($B10,Şablon!$E$3:$Q$255,2,FALSE) -> 11.00.00 (M) DÖKME ÇİMENTO MALZEME | E10: =VLOOKUP($B10,Şablon!$E$3:$Q$255,3,FALSE) -> B KATEGORİ | F10: =VLOOKUP($B10,Şablon!$E$3:$Q$255,4,FALSE) -> İNŞ | G10: =I10-VLOOKUP($B10,Şablon!$E$3:$Q$255,5,FALSE) -> -70 | I10: =K10-VLOOKUP($B10,Şablon!$E$3:$Q$255,6,FALSE) -> -70 | K10: =M10-VLOOKUP($B10,Şablon!$E$3:$Q$255,7,FALSE) -> -56 | M10: =O10-VLOOKUP($B10,Şablon!$E$3:$Q$255,8,FALSE) -> -49 | O10: =Q10-VLOOKUP($B10,Şablon!$E$3:$Q$255,9,FALSE) -> -28 | Q10: =S10-VLOOKUP($B10,Şablon!$E$3:$Q$255,10,FALSE) -> -21 | S10: =U10-(VLOOKUP($B10,Şablon!$E$3:$Q$255,11,FALSE)+VLOOKUP($B10,Şablon!$E$3:$Q$255,12,FALSE)) -> -7
B11: =Şablon!E10 -> IHL.3028.008/1 | C11: =VLOOKUP($B11,Şablon!$E$3:$Q$255,2,FALSE) -> 13.01.00 (M) HAZIR BETON MALZEME | E11: =VLOOKUP($B11,Şablon!$E$3:$Q$255,3,FALSE) -> B KATEGORİ | F11: =VLOOKUP($B11,Şablon!$E$3:$Q$255,4,FALSE) -> İNŞ | G11: =I11-VLOOKUP($B11,Şablon!$E$3:$Q$255,5,FALSE) -> -70 | I11: =K11-VLOOKUP($B11,Şablon!$E$3:$Q$255,6,FALSE) -> -70 | K11: =M11-VLOOKUP($B11,Şablon!$E$3:$Q$255,7,FALSE) -> -56 | M11: =O11-VLOOKUP($B11,Şablon!$E$3:$Q$255,8,FALSE) -> -49 | O11: =Q11-VLOOKUP($B11,Şablon!$E$3:$Q$255,9,FALSE) -> -28 | Q11: =S11-VLOOKUP($B11,Şablon!$E$3:$Q$255,10,FALSE) -> -21 | S11: =U11-(VLOOKUP($B11,Şablon!$E$3:$Q$255,11,FALSE)+VLOOKUP($B11,Şablon!$E$3:$Q$255,12,FALSE)) -> -7
B12: =Şablon!E11 -> IHL.3028.009/1 | C12: =VLOOKUP($B12,Şablon!$E$3:$Q$255,2,FALSE) -> 09.02.00 HAFRİYAT | E12: =VLOOKUP($B12,Şablon!$E$3:$Q$255,3,FALSE) -> A KATEGORİ | F12: =VLOOKUP($B12,Şablon!$E$3:$Q$255,4,FALSE) -> İNŞ | G12: =I12-VLOOKUP($B12,Şablon!$E$3:$Q$255,5,FALSE) -> -87 | I12: =K12-VLOOKUP($B12,Şablon!$E$3:$Q$255,6,FALSE) -> -87 | K12: =M12-VLOOKUP($B12,Şablon!$E$3:$Q$255,7,FALSE) -> -73 | M12: =O12-VLOOKUP($B12,Şablon!$E$3:$Q$255,8,FALSE) -> -59 | O12: =Q12-VLOOKUP($B12,Şablon!$E$3:$Q$255,9,FALSE) -> -31 | Q12: =S12-VLOOKUP($B12,Şablon!$E$3:$Q$255,10,FALSE) -> -21 | S12: =U12-(VLOOKUP($B12,Şablon!$E$3:$Q$255,11,FALSE)+VLOOKUP($B12,Şablon!$E$3:$Q$255,12,FALSE)) -> -7
B13: =Şablon!E12 -> IHL.3028.010/1 | C13: =VLOOKUP($B13,Şablon!$E$3:$Q$255,2,FALSE) -> 11.02.00 ZEMİN İYİLEŞTİRME | E13: =VLOOKUP($B13,Şablon!$E$3:$Q$255,3,FALSE) -> A KATEGORİ | F13: =VLOOKUP($B13,Şablon!$E$3:$Q$255,4,FALSE) -> İNŞ | G13: =I13-VLOOKUP($B13,Şablon!$E$3:$Q$255,5,FALSE) -> -94 | I13: =K13-VLOOKUP($B13,Şablon!$E$3:$Q$255,6,FALSE) -> -94 | K13: =M13-VLOOKUP($B13,Şablon!$E$3:$Q$255,7,FALSE) -> -80 | M13: =O13-VLOOKUP($B13,Şablon!$E$3:$Q$255,8,FALSE) -> -66 | O13: =Q13-VLOOKUP($B13,Şablon!$E$3:$Q$255,9,FALSE) -> -38 | Q13: =S13-VLOOKUP($B13,Şablon!$E$3:$Q$255,10,FALSE) -> -28 | S13: =U13-(VLOOKUP($B13,Şablon!$E$3:$Q$255,11,FALSE)+VLOOKUP($B13,Şablon!$E$3:$Q$255,12,FALSE)) -> -14
B14: =Şablon!E13 -> IHL.3028.011/1 | C14: =VLOOKUP($B14,Şablon!$E$3:$Q$255,2,FALSE) -> 11.00.00 KAZIK BAŞI KIRIM İŞLERİ | E14: =VLOOKUP($B14,Şablon!$E$3:$Q$255,3,FALSE) -> B KATEGORİ | F14: =VLOOKUP($B14,Şablon!$E$3:$Q$255,4,FALSE) -> İNŞ | G14: =I14-VLOOKUP($B14,Şablon!$E$3:$Q$255,5,FALSE) -> -56 | I14: =K14-VLOOKUP($B14,Şablon!$E$3:$Q$255,6,FALSE) -> -56 | K14: =M14-VLOOKUP($B14,Şablon!$E$3:$Q$255,7,FALSE) -> -42 | M14: =O14-VLOOKUP($B14,Şablon!$E$3:$Q$255,8,FALSE) -> -35 | O14: =Q14-VLOOKUP($B14,Şablon!$E$3:$Q$255,9,FALSE) -> -21 | Q14: =S14-VLOOKUP($B14,Şablon!$E$3:$Q$255,10,FALSE) -> -14 | S14: =U14-(VLOOKUP($B14,Şablon!$E$3:$Q$255,11,FALSE)+VLOOKUP($B14,Şablon!$E$3:$Q$255,12,FALSE)) -> -7
B15: =Şablon!E14 -> IHL.3028.012/1 | C15: =VLOOKUP($B15,Şablon!$E$3:$Q$255,2,FALSE) -> 23.01.00 TEMEL ALTI YALITIM | E15: =VLOOKUP($B15,Şablon!$E$3:$Q$255,3,FALSE) -> A KATEGORİ | F15: =VLOOKUP($B15,Şablon!$E$3:$Q$255,4,FALSE) -> İNŞ | G15: =I15-VLOOKUP($B15,Şablon!$E$3:$Q$255,5,FALSE) -> -101 | I15: =K15-VLOOKUP($B15,Şablon!$E$3:$Q$255,6,FALSE) -> -101 | K15: =M15-VLOOKUP($B15,Şablon!$E$3:$Q$255,7,FALSE) -> -87 | M15: =O15-VLOOKUP($B15,Şablon!$E$3:$Q$255,8,FALSE) -> -73 | O15: =Q15-VLOOKUP($B15,Şablon!$E$3:$Q$255,9,FALSE) -> -45 | Q15: =S15-VLOOKUP($B15,Şablon!$E$3:$Q$255,10,FALSE) -> -35 | S15: =U15-(VLOOKUP($B15,Şablon!$E$3:$Q$255,11,FALSE)+VLOOKUP($B15,Şablon!$E$3:$Q$255,12,FALSE)) -> -14
... B146: =Şablon!E145 -> IHL.3028.140/1 | C146: =VLOOKUP($B146,Şablon!$E$3:$Q$255,2,FALSE) -> 35.01.00 ASANSÖR İŞLERİ | E146: =VLOOKUP($B146,Şablon!$E$3:$Q$255,3,FALSE) -> A KATEGORİ | F146: =VLOOKUP($B146,Şablon!$E$3:$Q$255,4,FALSE) -> ELK | G146: =I146-VLOOKUP($B146,Şablon!$E$3:$Q$255,5,FALSE) -> -103 | I146: =K146-VLOOKUP($B146,Şablon!$E$3:$Q$255,6,FALSE) -> -103 | K146: =M146-VLOOKUP($B146,Şablon!$E$3:$Q$255,7,FALSE) -> -89 | M146: =O146-VLOOKUP($B146,Şablon!$E$3:$Q$255,8,FALSE) -> -68 | O146: =Q146-VLOOKUP($B146,Şablon!$E$3:$Q$255,9,FALSE) -> -38 | Q146: =S146-VLOOKUP($B146,Şablon!$E$3:$Q$255,10,FALSE) -> -28 | S146: =U146-(VLOOKUP($B146,Şablon!$E$3:$Q$255,11,FALSE)+VLOOKUP($B146,Şablon!$E$3:$Q$255,12,FALSE)) -> -14

Sheet Rapor
B1: ='Satınalma Takvimi Veri Girişi'!B1 -> 3028 - MONA
B2: İHALE NO | C2: İHALE KODU | D2: İHALE ADI / AÇIKLAMA | E2: İHALE KATEGORİ | F2: İHALE BÖLÜMÜ | G2: TASARIM KARARLARININ VERİLMESİ | K2: PROJE YAYIN TARİHİ | O2: TALEP (SAT) TARİHİ | S2: İHALE YAYINI | W2: YÖNETİME SUNUM TARİHİ | AA2: İHALE KARAR TARİHİ | AE2: SÖZLEŞME İMZA TARİHİ | AI2: İMALAT BAŞLANGIÇ TARİHİ | AK2: SAT NO | AL2: FİRMA ADI | AM2: SAS NO | AN2: SÖZLEŞME TUTARI TL | AO2: SÖZLEŞME TUTARI USD | AP2: SÖZLEŞME TUTARI EURO | AQ2: DİZAYN İLERLEME YÜZDESİ
G3: PLANLANAN SÜRE | H3: PLANLANAN TARİH | I3: GERÇEKLEŞEN SÜRE | J3: GERÇEKLEŞEN TARİH | K3: PLANLANAN SÜRE | L3: PLANLANAN TARİH | M3: GERÇEKLEŞEN SÜRE | N3: GERÇEKLEŞEN TARİH | O3: PLANLANAN SÜRE | P3: PLANLANAN TARİH | Q3: GERÇEKLEŞEN SÜRE | R3: GERÇEKLEŞEN TARİH | S3: PLANLANAN SÜRE | T3: PLANLANAN TARİH | U3: GERÇEKLEŞEN SÜRE | V3: GERÇEKLEŞEN TARİH | W3: PLANLANAN SÜRE | X3: PLANLANAN TARİH | Y3: GERÇEKLEŞEN SÜRE | Z3: GERÇEKLEŞEN TARİH | AA3: PLANLANAN SÜRE | AB3: PLANLANAN TARİH | AC3: GERÇEKLEŞEN SÜRE | AD3: GERÇEKLEŞEN TARİH | AE3: PLANLANAN SÜRE | AF3: PLANLANAN TARİH | AG3: GERÇEKLEŞEN SÜRE | AH3: GERÇEKLEŞEN TARİH | AI3: PLANLANAN | AJ3: GERÇEKLEŞEN
B4: =Şablon!E3 -> IHL.3028.001/1 | C4: =VLOOKUP($B4,Şablon!$E$3:$Q$255,2,FALSE) -> 09.01.00 YIKIM İŞLERİ | D4: =IF(VLOOKUP($B4,'Satınalma Takvimi Veri Girişi'!$B$4:$AC$146,3,FALSE)<>"",VLOOKUP($B4,'Satınalma Takvimi Veri Girişi'!$B$4:$AC$146,3,FALSE),"") | E4: =VLOOKUP($B4,Şablon!$E$3:$Q$255,3,FALSE) -> B KATEGORİ | F4: =VLOOKUP($B4,Şablon!$E$3:$Q$255,4,FALSE) -> İNŞ | G4: =VLOOKUP($B4,Şablon!$E$3:$Q$255,5,FALSE) -> 0 | H4: =IFERROR(L4-G4,"") | I4: =IFERROR(N4-J4,"") | J4: =IF(VLOOKUP($B4,'Satınalma Takvimi Veri Girişi'!$B$4:$AC$146,7,FALSE)<>"",VLOOKUP($B4,'Satınalma Takvimi Veri Girişi'!$B$4:$AC$146,7,FALSE),"") | K4: =VLOOKUP($B4,Şablon!$E$3:$Q$255,6,FALSE) -> 14 | L4: =IFERROR(P4-K4,"") | M4: =IFERROR(R4-N4,"") | N4: =IF(VLOOKUP($B4,'Satınalma Takvimi Veri Girişi'!$B$4:$AC$146,9,FALSE)<>"",VLOOKUP($B4,'Satınalma Takvimi Veri Girişi'!$B$4:$AC$146,9,FALSE),"") | O4: =VLOOKUP($B4,Şablon!$E$3:$Q$255,7,FALSE) -> 7 | P4: =IFERROR(T4-O4,"") | Q4: =IFERROR(V4-R4,"") | R4: =IF(VLOOKUP($B4,'Satınalma Takvimi Veri Girişi'!$B$4:$AC$146,11,FALSE)<>"",VLOOKUP($B4,'Satınalma Takvimi Veri Girişi'!$B$4:$AC$146,11,FALSE),"") | S4: =VLOOKUP($B4,Şablon!$E$3:$Q$255,8,FALSE) -> 14 | T4: =IFERROR(X4-S4,"") | U4: =IFERROR(Z4-V4,"") | V4: =IF(VLOOKUP($B4,'Satınalma Takvimi Veri Girişi'!$B$4:$AC$146,13,FALSE)<>"",VLOOKUP($B4,'Satınalma Takvimi Veri Girişi'!$B$4:$AC$146,13,FALSE),"") | W4: =VLOOKUP($B4,Şablon!$E$3:$Q$255,9,FALSE) -> 7 | X4: =IFERROR(AB4-W4,"") | Y4: =IFERROR(AD4-Z4,"") | Z4: =IF(VLOOKUP($B4,'Satınalma Takvimi Veri Girişi'!$B$4:$AC$146,15,FALSE)<>"",VLOOKUP($B4,'Satınalma Takvimi Veri Girişi'!$B$4:$AC$146,15,FALSE),"") | AA4: =VLOOKUP($B4,Şablon!$E$3:$Q$255,10,FALSE) -> 7 | AB4: =IFERROR(AF4-AA4,"") | AC4: =IFERROR(AH4-AD4,"") | AD4: =IF(VLOOKUP($B4,'Satınalma Takvimi Veri Girişi'!$B$4:$AC$146,17,FALSE)<>"",VLOOKUP($B4,'Satınalma Takvimi Veri Girişi'!$B$4:$AC$146,17,FALSE),"") | AE4: =(VLOOKUP($B4,Şablon!$E$3:$Q$255,11,FALSE)+VLOOKUP($B4,Şablon!$E$3:$Q$255,12,FALSE)) -> 7 | AF4: =IFERROR(AI4-AE4,"") | AG4: =IFERROR(AJ4-AH4,"") | AH4: =IF(VLOOKUP($B4,'Satınalma Takvimi Veri Girişi'!$B$4:$AC$146,19,FALSE)<>"",VLOOKUP($B4,'Satınalma Takvimi Veri Girişi'!$B$4:$AC$146,19,FALSE),"") | AI4: =IF(VLOOKUP($B4,'Satınalma Takvimi Veri Girişi'!$B$4:$AC$146,20,FALSE)<>"",VLOOKUP($B4,'Satınalma Takvimi Veri Girişi'!$B$4:$AC$146,20,FALSE),"") | AJ4: =IF(VLOOKUP($B4,'Satınalma Takvimi Veri Girişi'!$B$4:$AC$146,21,FALSE)<>"",VLOOKUP($B4,'Satınalma Takvimi Veri Girişi'!$B$4:$AC$146,21,FALSE),"") | AK4: =IF(VLOOKUP($B4,'Satınalma Takvimi Veri Girişi'!$B$4:$AC$146,22,FALSE)<>"",VLOOKUP($B4,'Satınalma Takvimi Veri Girişi'!$B$4:$AC$146,22,FALSE),"") | AL4: =IF(VLOOKUP($B4,'Satınalma Takvimi Veri Girişi'!$B$4:$AC$146,23,FALSE)<>"",VLOOKUP($B4,'Satınalma Takvimi Veri Girişi'!$B$4:$AC$146,23,FALSE),"") | AM4: =IF(VLOOKUP($B4,'Satınalma Takvimi Veri Girişi'!$B$4:$AC$146,24,FALSE)<>"",VLOOKUP($B4,'Satınalma Takvimi Veri Girişi'!$B$4:$AC$146,24,FALSE),"") | AN4: =IF(VLOOKUP($B4,'Satınalma Takvimi Veri Girişi'!$B$4:$AC$146,25,FALSE)<>"",VLOOKUP($B4,'Satınalma Takvimi Veri Girişi'!$B$4:$AC$146,25,FALSE),"") | AO4: =IF(VLOOKUP($B4,'Satınalma Takvimi Veri Girişi'!$B$4:$AC$146,26,FALSE)<>"",VLOOKUP($B4,'Satınalma Takvimi Veri Girişi'!$B$4:$AC$146,26,FALSE),"") | AP4: =IF(VLOOKUP($B4,'Satınalma Takvimi Veri Girişi'!$B$4:$AC$146,27,FALSE)<>"",VLOOKUP($B4,'Satınalma Takvimi Veri Girişi'!$B$4:$AC$146,27,FALSE),"") | AQ4: =IF(VLOOKUP($B4,'Satınalma Takvimi Veri Girişi'!$B$4:$AC$146,28,FALSE)<>"",VLOOKUP($B4,'Satınalma Takvimi Veri Girişi'!$B$4:$AC$146,28,FALSE),"")
B5: =Şablon!E4 -> IHL.3028.002/1 | C5: =VLOOKUP($B5,Şablon!$E$3:$Q$255,2,FALSE) -> 05.03.00 ZEMİN ETÜDÜ | D5: =IF(VLOOKUP($B5,'Satınalma Takvimi Veri Girişi'!$B$4:$AC$146,3,FALSE)<>"",VLOOKUP($B5,'Satınalma Takvimi Veri Girişi'!$B$4:$AC$146,3,FALSE),"") | E5: =VLOOKUP($B5,Şablon!$E$3:$Q$255,3,FALSE) -> C KATEGORİ | F5: =VLOOKUP($B5,Şablon!$E$3:$Q$255,4,FALSE) -> İNŞ | G5: =VLOOKUP($B5,Şablon!$E$3:$Q$255,5,FALSE) -> 0 | H5: =IFERROR(L5-G5,"") | I5: =IFERROR(N5-J5,"") | J5: =IF(VLOOKUP($B5,'Satınalma Takvimi Veri Girişi'!$B$4:$AC$146,7,FALSE)<>"",VLOOKUP($B5,'Satınalma Takvimi Veri Girişi'!$B$4:$AC$146,7,FALSE),"") | K5: =VLOOKUP($B5,Şablon!$E$3:$Q$255,6,FALSE) -> 14 | L5: =IFERROR(P5-K5,"") | M5: =IFERROR(R5-N5,"") | N5: =IF(VLOOKUP($B5,'Satınalma Takvimi Veri Girişi'!$B$4:$AC$146,9,FALSE)<>"",VLOOKUP($B5,'Satınalma Takvimi Veri Girişi'!$B$4:$AC$146,9,FALSE),"") | O5: =VLOOKUP($B5,Şablon!$E$3:$Q$255,7,FALSE) -> 7 | P5: =IFERROR(T5-O5,"") | Q5: =IFERROR(V5-R5,"") | R5: =IF(VLOOKUP($B5,'Satınalma Takvimi Veri Girişi'!$B$4:$AC$146,11,FALSE)<>"",VLOOKUP($B5,'Satınalma Takvimi Veri Girişi'!$B$4:$AC$146,11,FALSE),"") | S5: =VLOOKUP($B5,Şablon!$E$3:$Q$255,8,FALSE) -> 14 | T5: =IFERROR(X5-S5,"") | U5: =IFERROR(Z5-V5,"") | V5: =IF(VLOOKUP($B5,'Satınalma Takvimi Veri Girişi'!$B$4:$AC$146,13,FALSE)<>"",VLOOKUP($B5,'Satınalma Takvimi Veri Girişi'!$B$4:$AC$146,13,FALSE),"") | W5: =VLOOKUP($B5,Şablon!$E$3:$Q$255,9,FALSE) -> 7 | X5: =IFERROR(AB5-W5,"") | Y5: =IFERROR(AD5-Z5,"") | Z5: =IF(VLOOKUP($B5,'Satınalma Takvimi Veri Girişi'!$B$4:$AC$146,15,FALSE)<>"",VLOOKUP($B5,'Satınalma Takvimi Veri Girişi'!$B$4:$AC$146,15,FALSE),"") | AA5: =VLOOKUP($B5,Şablon!$E$3:$Q$255,10,FALSE) -> 7 | AB5: =IFERROR(AF5-AA5,"") | AC5: =IFERROR(AH5-AD5,"") | AD5: =IF(VLOOKUP($B5,'Satınalma Takvimi Veri Girişi'!$B$4:$AC$146,17,FALSE)<>"",VLOOKUP($B5,'Satınalma Takvimi Veri Girişi'!$B$4:$AC$146,17,FALSE),"") | AE5: =(VLOOKUP($B5,Şablon!$E$3:$Q$255,11,FALSE)+VLOOKUP($B5,Şablon!$E$3:$Q$255,12,FALSE)) -> 7 | AF5: =IFERROR(AI5-AE5,"") | AG5: =IFERROR(AJ5-AH5,"") | AH5: =IF(VLOOKUP($B5,'Satınalma Takvimi Veri Girişi'!$B$4:$AC$146,19,FALSE)<>"",VLOOKUP($B5,'Satınalma Takvimi Veri Girişi'!$B$4:$AC$146,19,FALSE),"") | AI5: =IF(VLOOKUP($B5,'Satınalma Takvimi Veri Girişi'!$B$4:$AC$146,20,FALSE)<>"",VLOOKUP($B5,'Satınalma Takvimi Veri Girişi'!$B$4:$AC$146,20,FALSE),"") | AJ5: =IF(VLOOKUP($B5,'Satınalma Takvimi Veri Girişi'!$B$4:$AC$146,21,FALSE)<>"",VLOOKUP($B5,'Satınalma Takvimi Veri Girişi'!$B$4:$AC$146,21,FALSE),"") | AK5: =IF(VLOOKUP($B5,'Satınalma Takvimi Veri Girişi'!$B$4:$AC$146,22,FALSE)<>"",VLOOKUP($B5,'Satınalma Takvimi Veri Girişi'!$B$4:$AC$146,22,FALSE),"") | AL5: =IF(VLOOKUP($B5,'Satınalma Takvimi Veri Girişi'!$B$4:$AC$146,23,FALSE)<>"",VLOOKUP($B5,'Satınalma Takvimi Veri Girişi'!$B$4:$AC$146,23,FALSE),"") | AM5: =IF(VLOOKUP($B5,'Satınalma Takvimi Veri Girişi'!$B$4:$AC$146,24,FALSE)<>"",VLOOKUP($B5,'Satınalma Takvimi Veri Girişi'!$B$4:$AC$146,24,FALSE),"") | AN5: =IF(VLOOKUP($B5,'Satınalma Takvimi Veri Girişi'!$B$4:$AC$146,25,FALSE)<>"",VLOOKUP($B5,'Satınalma Takvimi Veri Girişi'!$B$4:$AC$146,25,FALSE),"") | AO5: =IF(VLOOKUP($B5,'Satınalma Takvimi Veri Girişi'!$B$4:$AC$146,26,FALSE)<>"",VLOOKUP($B5,'Satınalma Takvimi Veri Girişi'!$B$4:$AC$146,26,FALSE),"") | AP5: =IF(VLOOKUP($B5,'Satınalma Takvimi Veri Girişi'!$B$4:$AC$146,27,FALSE)<>"",VLOOKUP($B5,'Satınalma Takvimi Veri Girişi'!$B$4:$AC$146,27,FALSE),"") | AQ5: =IF(VLOOKUP($B5,'Satınalma Takvimi Veri Girişi'!$B$4:$AC$146,28,FALSE)<>"",VLOOKUP($B5,'Satınalma Takvimi Veri Girişi'!$B$4:$AC$146,28,FALSE),"")
B6: =Şablon!E5 -> IHL.3028.003/1 | C6: =VLOOKUP($B6,Şablon!$E$3:$Q$255,2,FALSE) -> 01.18.00 OSGB İŞLERİ | D6: =IF(VLOOKUP($B6,'Satınalma Takvimi Veri Girişi'!$B$4:$AC$146,3,FALSE)<>"",VLOOKUP($B6,'Satınalma Takvimi Veri Girişi'!$B$4:$AC$146,3,FALSE),"") | E6: =VLOOKUP($B6,Şablon!$E$3:$Q$255,3,FALSE) -> C KATEGORİ | F6: =VLOOKUP($B6,Şablon!$E$3:$Q$255,4,FALSE) -> İNŞ | G6: =VLOOKUP($B6,Şablon!$E$3:$Q$255,5,FALSE) -> 0 | H6: =IFERROR(L6-G6,"") | I6: =IFERROR(N6-J6,"") | J6: =IF(VLOOKUP($B6,'Satınalma Takvimi Veri Girişi'!$B$4:$AC$146,7,FALSE)<>"",VLOOKUP($B6,'Satınalma Takvimi Veri Girişi'!$B$4:$AC$146,7,FALSE),"") | K6: =VLOOKUP($B6,Şablon!$E$3:$Q$255,6,FALSE) -> 14 | L6: =IFERROR(P6-K6,"") | M6: =IFERROR(R6-N6,"") | N6: =IF(VLOOKUP($B6,'Satınalma Takvimi Veri Girişi'!$B$4:$AC$146,9,FALSE)<>"",VLOOKUP($B6,'Satınalma Takvimi Veri Girişi'!$B$4:$AC$146,9,FALSE),"") | O6: =VLOOKUP($B6,Şablon!$E$3:$Q$255,7,FALSE) -> 7 | P6: =IFERROR(T6-O6,"") | Q6: =IFERROR(V6-R6,"") | R6: =IF(VLOOKUP($B6,'Satınalma Takvimi Veri Girişi'!$B$4:$AC$146,11,FALSE)<>"",VLOOKUP($B6,'Satınalma Takvimi Veri Girişi'!$B$4:$AC$146,11,FALSE),"") | S6: =VLOOKUP($B6,Şablon!$E$3:$Q$255,8,FALSE) -> 14 | T6: =IFERROR(X6-S6,"") | U6: =IFERROR(Z6-V6,"") | V6: =IF(VLOOKUP($B6,'Satınalma Takvimi Veri Girişi'!$B$4:$AC$146,13,FALSE)<>"",VLOOKUP($B6,'Satınalma Takvimi Veri Girişi'!$B$4:$AC$146,13,FALSE),"") | W6: =VLOOKUP($B6,Şablon!$E$3:$Q$255,9,FALSE) -> 7 | X6: =IFERROR(AB6-W6,"") | Y6: =IFERROR(AD6-Z6,"") | Z6: =IF(VLOOKUP($B6,'Satınalma Takvimi Veri Girişi'!$B$4:$AC$146,15,FALSE)<>"",VLOOKUP($B6,'Satınalma Takvimi Veri Girişi'!$B$4:$AC$146,15,FALSE),"") | AA6: =VLOOKUP($B6,Şablon!$E$3:$Q$255,10,FALSE) -> 7 | AB6: =IFERROR(AF6-AA6,"") | AC6: =IFERROR(AH6-AD6,"") | AD6: =IF(VLOOKUP($B6,'Satınalma Takvimi Veri Girişi'!$B$4:$AC$146,17,FALSE)<>"",VLOOKUP($B6,'Satınalma Takvimi Veri Girişi'!$B$4:$AC$146,17,FALSE),"") | AE6: =(VLOOKUP($B6,Şablon!$E$3:$Q$255,11,FALSE)+VLOOKUP($B6,Şablon!$E$3:$Q$255,12,FALSE)) -> 7 | AF6: =IFERROR(AI6-AE6,"") | AG6: =IFERROR(AJ6-AH6,"") | AH6: =IF(VLOOKUP($B6,'Satınalma Takvimi Veri Girişi'!$B$4:$AC$146,19,FALSE)<>"",VLOOKUP($B6,'Satınalma Takvimi Veri Girişi'!$B$4:$AC$146,19,FALSE),"") | AI6: =IF(VLOOKUP($B6,'Satınalma Takvimi Veri Girişi'!$B$4:$AC$146,20,FALSE)<>"",VLOOKUP($B6,'Satınalma Takvimi Veri Girişi'!$B$4:$AC$146,20,FALSE),"") | AJ6: =IF(VLOOKUP($B6,'Satınalma Takvimi Veri Girişi'!$B$4:$AC$146,21,FALSE)<>"",VLOOKUP($B6,'Satınalma Takvimi Veri Girişi'!$B$4:$AC$146,21,FALSE),"") | AK6: =IF(VLOOKUP($B6,'Satınalma Takvimi Veri Girişi'!$B$4:$AC$146,22,FALSE)<>"",VLOOKUP($B6,'Satınalma Takvimi Veri Girişi'!$B$4:$AC$146,22,FALSE),"") | AL6: =IF(VLOOKUP($B6,'Satınalma Takvimi Veri Girişi'!$B$4:$AC$146,23,FALSE)<>"",VLOOKUP($B6,'Satınalma Takvimi Veri Girişi'!$B$4:$AC$146,23,FALSE),"") | AM6: =IF(VLOOKUP($B6,'Satınalma Takvimi Veri Girişi'!$B$4:$AC$146,24,FALSE)<>"",VLOOKUP($B6,'Satınalma Takvimi Veri Girişi'!$B$4:$AC$146,24,FALSE),"") | AN6: =IF(VLOOKUP($B6,'Satınalma Takvimi Veri Girişi'!$B$4:$AC$146,25,FALSE)<>"",VLOOKUP($B6,'Satınalma Takvimi Veri Girişi'!$B$4:$AC$146,25,FALSE),"") | AO6: =IF(VLOOKUP($B6,'Satınalma Takvimi Veri Girişi'!$B$4:$AC$146,26,FALSE)<>"",VLOOKUP($B6,'Satınalma Takvimi Veri Girişi'!$B$4:$AC$146,26,FALSE),"") | AP6: =IF(VLOOKUP($B6,'Satınalma Takvimi Veri Girişi'!$B$4:$AC$146,27,FALSE)<>"",VLOOKUP($B6,'Satınalma Takvimi Veri Girişi'!$B$4:$AC$146,27,FALSE),"") | AQ6: =IF(VLOOKUP($B6,'Satınalma Takvimi Veri Girişi'!$B$4:$AC$146,28,FALSE)<>"",VLOOKUP($B6,'Satınalma Takvimi Veri Girişi'!$B$4:$AC$146,28,FALSE),"")
B7: =Şablon!E6 -> IHL.3028.004/1 | C7: =VLOOKUP($B7,Şablon!$E$3:$Q$255,2,FALSE) -> 07.01.00 MOBİLİZASYON İŞLERİ | D7: =IF(VLOOKUP($B7,'Satınalma Takvimi Veri Girişi'!$B$4:$AC$146,3,FALSE)<>"",VLOOKUP($B7,'Satınalma Takvimi Veri Girişi'!$B$4:$AC$146,3,FALSE),"") | E7: =VLOOKUP($B7,Şablon!$E$3:$Q$255,3,FALSE) -> C KATEGORİ | F7: =VLOOKUP($B7,Şablon!$E$3:$Q$255,4,FALSE) -> İNŞ | G7: =VLOOKUP($B7,Şablon!$E$3:$Q$255,5,FALSE) -> 0 | H7: =IFERROR(L7-G7,"") | I7: =IFERROR(N7-J7,"") | J7: =IF(VLOOKUP($B7,'Satınalma Takvimi Veri Girişi'!$B$4:$AC$146,7,FALSE)<>"",VLOOKUP($B7,'Satınalma Takvimi Veri Girişi'!$B$4:$AC$146,7,FALSE),"") | K7: =VLOOKUP($B7,Şablon!$E$3:$Q$255,6,FALSE) -> 14 | L7: =IFERROR(P7-K7,"") | M7: =IFERROR(R7-N7,"") | N7: =IF(VLOOKUP($B7,'Satınalma Takvimi Veri Girişi'!$B$4:$AC$146,9,FALSE)<>"",VLOOKUP($B7,'Satınalma Takvimi Veri Girişi'!$B$4:$AC$146,9,FALSE),"") | O7: =VLOOKUP($B7,Şablon!$E$3:$Q$255,7,FALSE) -> 7 | P7: =IFERROR(T7-O7,"") | Q7: =IFERROR(V7-R7,"") | R7: =IF(VLOOKUP($B7,'Satınalma Takvimi Veri Girişi'!$B$4:$AC$146,11,FALSE)<>"",VLOOKUP($B7,'Satınalma Takvimi Veri Girişi'!$B$4:$AC$146,11,FALSE),"") | S7: =VLOOKUP($B7,Şablon!$E$3:$Q$255,8,FALSE) -> 28 | T7: =IFERROR(X7-S7,"") | U7: =IFERROR(Z7-V7,"") | V7: =IF(VLOOKUP($B7,'Satınalma Takvimi Veri Girişi'!$B$4:$AC$146,13,FALSE)<>"",VLOOKUP($B7,'Satınalma Takvimi Veri Girişi'!$B$4:$AC$146,13,FALSE),"") | W7: =VLOOKUP($B7,Şablon!$E$3:$Q$255,9,FALSE) -> 7 | X7: =IFERROR(AB7-W7,"") | Y7: =IFERROR(AD7-Z7,"") | Z7: =IF(VLOOKUP($B7,'Satınalma Takvimi Veri Girişi'!$B$4:$AC$146,15,FALSE)<>"",VLOOKUP($B7,'Satınalma Takvimi Veri Girişi'!$B$4:$AC$146,15,FALSE),"") | AA7: =VLOOKUP($B7,Şablon!$E$3:$Q$255,10,FALSE) -> 14 | AB7: =IFERROR(AF7-AA7,"") | AC7: =IFERROR(AH7-AD7,"") | AD7: =IF(VLOOKUP($B7,'Satınalma Takvimi Veri Girişi'!$B$4:$AC$146,17,FALSE)<>"",VLOOKUP($B7,'Satınalma Takvimi Veri Girişi'!$B$4:$AC$146,17,FALSE),"") | AE7: =(VLOOKUP($B7,Şablon!$E$3:$Q$255,11,FALSE)+VLOOKUP($B7,Şablon!$E$3:$Q$255,12,FALSE)) -> 35 | AF7: =IFERROR(AI7-AE7,"") | AG7: =IFERROR(AJ7-AH7,"") | AH7: =IF(VLOOKUP($B7,'Satınalma Takvimi Veri Girişi'!$B$4:$AC$146,19,FALSE)<>"",VLOOKUP($B7,'Satınalma Takvimi Veri Girişi'!$B$4:$AC$146,19,FALSE),"") | AI7: =IF(VLOOKUP($B7,'Satınalma Takvimi Veri Girişi'!$B$4:$AC$146,20,FALSE)<>"",VLOOKUP($B7,'Satınalma Takvimi Veri Girişi'!$B$4:$AC$146,20,FALSE),"") | AJ7: =IF(VLOOKUP($B7,'Satınalma Takvimi Veri Girişi'!$B$4:$AC$146,21,FALSE)<>"",VLOOKUP($B7,'Satınalma Takvimi Veri Girişi'!$B$4:$AC$146,21,FALSE),"") | AK7: =IF(VLOOKUP($B7,'Satınalma Takvimi Veri Girişi'!$B$4:$AC$146,22,FALSE)<>"",VLOOKUP($B7,'Satınalma Takvimi Veri Girişi'!$B$4:$AC$146,22,FALSE),"") | AL7: =IF(VLOOKUP($B7,'Satınalma Takvimi Veri Girişi'!$B$4:$AC$146,23,FALSE)<>"",VLOOKUP($B7,'Satınalma Takvimi Veri Girişi'!$B$4:$AC$146,23,FALSE),"") | AM7: =IF(VLOOKUP($B7,'Satınalma Takvimi Veri Girişi'!$B$4:$AC$146,24,FALSE)<>"",VLOOKUP($B7,'Satınalma Takvimi Veri Girişi'!$B$4:$AC$146,24,FALSE),"") | AN7: =IF(VLOOKUP($B7,'Satınalma Takvimi Veri Girişi'!$B$4:$AC$146,25,FALSE)<>"",VLOOKUP($B7,'Satınalma Takvimi Veri Girişi'!$B$4:$AC$146,25,FALSE),"") | AO7: =IF(VLOOKUP($B7,'Satınalma Takvimi Veri Girişi'!$B$4:$AC$146,26,FALSE)<>"",VLOOKUP($B7,'Satınalma Takvimi Veri Girişi'!$B$4:$AC$146,26,FALSE),"") | AP7: =IF(VLOOKUP($B7,'Satınalma Takvimi Veri Girişi'!$B$4:$AC$146,27,FALSE)<>"",VLOOKUP($B7,'Satınalma Takvimi Veri Girişi'!$B$4:$AC$146,27,FALSE),"") | AQ7: =IF(VLOOKUP($B7,'Satınalma Takvimi Veri Girişi'!$B$4:$AC$146,28,FALSE)<>"",VLOOKUP($B7,'Satınalma Takvimi Veri Girişi'!$B$4:$AC$146,28,FALSE),"")
B8: =Şablon!E7 -> IHL.3028.005/1 | C8: =VLOOKUP($B8,Şablon!$E$3:$Q$255,2,FALSE) -> 11.03.00 ZEMİN İYİLEŞTİRME TEST YAPILMASI | D8: =IF(VLOOKUP($B8,'Satınalma Takvimi Veri Girişi'!$B$4:$AC$146,3,FALSE)<>"",VLOOKUP($B8,'Satınalma Takvimi Veri Girişi'!$B$4:$AC$146,3,FALSE),"") | E8: =VLOOKUP($B8,Şablon!$E$3:$Q$255,3,FALSE) -> C KATEGORİ | F8: =VLOOKUP($B8,Şablon!$E$3:$Q$255,4,FALSE) -> İNŞ | G8: =VLOOKUP($B8,Şablon!$E$3:$Q$255,5,FALSE) -> 0 | H8: =IFERROR(L8-G8,"") | I8: =IFERROR(N8-J8,"") | J8: =IF(VLOOKUP($B8,'Satınalma Takvimi Veri Girişi'!$B$4:$AC$146,7,FALSE)<>"",VLOOKUP($B8,'Satınalma Takvimi Veri Girişi'!$B$4:$AC$146,7,FALSE),"") | K8: =VLOOKUP($B8,Şablon!$E$3:$Q$255,6,FALSE) -> 14 | L8: =IFERROR(P8-K8,"") | M8: =IFERROR(R8-N8,"") | N8: =IF(VLOOKUP($B8,'Satınalma Takvimi Veri Girişi'!$B$4:$AC$146,9,FALSE)<>"",VLOOKUP($B8,'Satınalma Takvimi Veri Girişi'!$B$4:$AC$146,9,FALSE),"") | O8: =VLOOKUP($B8,Şablon!$E$3:$Q$255,7,FALSE) -> 7 | P8: =IFERROR(T8-O8,"") | Q8: =IFERROR(V8-R8,"") | R8: =IF(VLOOKUP($B8,'Satınalma Takvimi Veri Girişi'!$B$4:$AC$146,11,FALSE)<>"",VLOOKUP($B8,'Satınalma Takvimi Veri Girişi'!$B$4:$AC$146,11,FALSE),"") | S8: =VLOOKUP($B8,Şablon!$E$3:$Q$255,8,FALSE) -> 28 | T8: =IFERROR(X8-S8,"") | U8: =IFERROR(Z8-V8,"") | V8: =IF(VLOOKUP($B8,'Satınalma Takvimi Veri Girişi'!$B$4:$AC$146,13,FALSE)<>"",VLOOKUP($B8,'Satınalma Takvimi Veri Girişi'!$B$4:$AC$146,13,FALSE),"") | W8: =VLOOKUP($B8,Şablon!$E$3:$Q$255,9,FALSE) -> 7 | X8: =IFERROR(AB8-W8,"") | Y8: =IFERROR(AD8-Z8,"") | Z8: =IF(VLOOKUP($B8,'Satınalma Takvimi Veri Girişi'!$B$4:$AC$146,15,FALSE)<>"",VLOOKUP($B8,'Satınalma Takvimi Veri Girişi'!$B$4:$AC$146,15,FALSE),"") | AA8: =VLOOKUP($B8,Şablon!$E$3:$Q$255,10,FALSE) -> 14 | AB8: =IFERROR(AF8-AA8,"") | AC8: =IFERROR(AH8-AD8,"") | AD8: =IF(VLOOKUP($B8,'Satınalma Takvimi Veri Girişi'!$B$4:$AC$146,17,FALSE)<>"",VLOOKUP($B8,'Satınalma Takvimi Veri Girişi'!$B$4:$AC$146,17,FALSE),"") | AE8: =(VLOOKUP($B8,Şablon!$E$3:$Q$255,11,FALSE)+VLOOKUP($B8,Şablon!$E$3:$Q$255,12,FALSE)) -> 28 | AF8: =IFERROR(AI8-AE8,"") | AG8: =IFERROR(AJ8-AH8,"") | AH8: =IF(VLOOKUP($B8,'Satınalma Takvimi Veri Girişi'!$B$4:$AC$146,19,FALSE)<>"",VLOOKUP($B8,'Satınalma Takvimi Veri Girişi'!$B$4:$AC$146,19,FALSE),"") | AI8: =IF(VLOOKUP($B8,'Satınalma Takvimi Veri Girişi'!$B$4:$AC$146,20,FALSE)<>"",VLOOKUP($B8,'Satınalma Takvimi Veri Girişi'!$B$4:$AC$146,20,FALSE),"") | AJ8: =IF(VLOOKUP($B8,'Satınalma Takvimi Veri Girişi'!$B$4:$AC$146,21,FALSE)<>"",VLOOKUP($B8,'Satınalma Takvimi Veri Girişi'!$B$4:$AC$146,21,FALSE),"") | AK8: =IF(VLOOKUP($B8,'Satınalma Takvimi Veri Girişi'!$B$4:$AC$146,22,FALSE)<>"",VLOOKUP($B8,'Satınalma Takvimi Veri Girişi'!$B$4:$AC$146,22,FALSE),"") | AL8: =IF(VLOOKUP($B8,'Satınalma Takvimi Veri Girişi'!$B$4:$AC$146,23,FALSE)<>"",VLOOKUP($B8,'Satınalma Takvimi Veri Girişi'!$B$4:$AC$146,23,FALSE),"") | AM8: =IF(VLOOKUP($B8,'Satınalma Takvimi Veri Girişi'!$B$4:$AC$146,24,FALSE)<>"",VLOOKUP($B8,'Satınalma Takvimi Veri Girişi'!$B$4:$AC$146,24,FALSE),"") | AN8: =IF(VLOOKUP($B8,'Satınalma Takvimi Veri Girişi'!$B$4:$AC$146,25,FALSE)<>"",VLOOKUP($B8,'Satınalma Takvimi Veri Girişi'!$B$4:$AC$146,25,FALSE),"") | AO8: =IF(VLOOKUP($B8,'Satınalma Takvimi Veri Girişi'!$B$4:$AC$146,26,FALSE)<>"",VLOOKUP($B8,'Satınalma Takvimi Veri Girişi'!$B$4:$AC$146,26,FALSE),"") | AP8: =IF(VLOOKUP($B8,'Satınalma Takvimi Veri Girişi'!$B$4:$AC$146,27,FALSE)<>"",VLOOKUP($B8,'Satınalma Takvimi Veri Girişi'!$B$4:$AC$146,27,FALSE),"") | AQ8: =IF(VLOOKUP($B8,'Satınalma Takvimi Veri Girişi'!$B$4:$AC$146,28,FALSE)<>"",VLOOKUP($B8,'Satınalma Takvimi Veri Girişi'!$B$4:$AC$146,28,FALSE),"")
B9: =Şablon!E8 -> IHL.3028.006/1 | C9: =VLOOKUP($B9,Şablon!$E$3:$Q$255,2,FALSE) -> 11.01.00 İKSA İŞLERİ | D9: =IF(VLOOKUP($B9,'Satınalma Takvimi Veri Girişi'!$B$4:$AC$146,3,FALSE)<>"",VLOOKUP($B9,'Satınalma Takvimi Veri Girişi'!$B$4:$AC$146,3,FALSE),"") | E9: =VLOOKUP($B9,Şablon!$E$3:$Q$255,3,FALSE) -> A KATEGORİ | F9: =VLOOKUP($B9,Şablon!$E$3:$Q$255,4,FALSE) -> İNŞ | G9: =VLOOKUP($B9,Şablon!$E$3:$Q$255,5,FALSE) -> 0 | H9: =IFERROR(L9-G9,"") | I9: =IFERROR(N9-J9,"") | J9: =IF(VLOOKUP($B9,'Satınalma Takvimi Veri Girişi'!$B$4:$AC$146,7,FALSE)<>"",VLOOKUP($B9,'Satınalma Takvimi Veri Girişi'!$B$4:$AC$146,7,FALSE),"") | K9: =VLOOKUP($B9,Şablon!$E$3:$Q$255,6,FALSE) -> 14 | L9: =IFERROR(P9-K9,"") | M9: =IFERROR(R9-N9,"") | N9: =IF(VLOOKUP($B9,'Satınalma Takvimi Veri Girişi'!$B$4:$AC$146,9,FALSE)<>"",VLOOKUP($B9,'Satınalma Takvimi Veri Girişi'!$B$4:$AC$146,9,FALSE),"") | O9: =VLOOKUP($B9,Şablon!$E$3:$Q$255,7,FALSE) -> 14 | P9: =IFERROR(T9-O9,"") | Q9: =IFERROR(V9-R9,"") | R9: =IF(VLOOKUP($B9,'Satınalma Takvimi Veri Girişi'!$B$4:$AC$146,11,FALSE)<>"",VLOOKUP($B9,'Satınalma Takvimi Veri Girişi'!$B$4:$AC$146,11,FALSE),"") | S9: =VLOOKUP($B9,Şablon!$E$3:$Q$255,8,FALSE) -> 28 | T9: =IFERROR(X9-S9,"") | U9: =IFERROR(Z9-V9,"") | V9: =IF(VLOOKUP($B9,'Satınalma Takvimi Veri Girişi'!$B$4:$AC$146,13,FALSE)<>"",VLOOKUP($B9,'Satınalma Takvimi Veri Girişi'!$B$4:$AC$146,13,FALSE),"") | W9: =VLOOKUP($B9,Şablon!$E$3:$Q$255,9,FALSE) -> 10 | X9: =IFERROR(AB9-W9,"") | Y9: =IFERROR(AD9-Z9,"") | Z9: =IF(VLOOKUP($B9,'Satınalma Takvimi Veri Girişi'!$B$4:$AC$146,15,FALSE)<>"",VLOOKUP($B9,'Satınalma Takvimi Veri Girişi'!$B$4:$AC$146,15,FALSE),"") | AA9: =VLOOKUP($B9,Şablon!$E$3:$Q$255,10,FALSE) -> 14 | AB9: =IFERROR(AF9-AA9,"") | AC9: =IFERROR(AH9-AD9,"") | AD9: =IF(VLOOKUP($B9,'Satınalma Takvimi Veri Girişi'!$B$4:$AC$146,17,FALSE)<>"",VLOOKUP($B9,'Satınalma Takvimi Veri Girişi'!$B$4:$AC$146,17,FALSE),"") | AE9: =(VLOOKUP($B9,Şablon!$E$3:$Q$255,11,FALSE)+VLOOKUP($B9,Şablon!$E$3:$Q$255,12,FALSE)) -> 14 | AF9: =IFERROR(AI9-AE9,"") | AG9: =IFERROR(AJ9-AH9,"") | AH9: =IF(VLOOKUP($B9,'Satınalma Takvimi Veri Girişi'!$B$4:$AC$146,19,FALSE)<>"",VLOOKUP($B9,'Satınalma Takvimi Veri Girişi'!$B$4:$AC$146,19,FALSE),"") | AI9: =IF(VLOOKUP($B9,'Satınalma Takvimi Veri Girişi'!$B$4:$AC$146,20,FALSE)<>"",VLOOKUP($B9,'Satınalma Takvimi Veri Girişi'!$B$4:$AC$146,20,FALSE),"") | AJ9: =IF(VLOOKUP($B9,'Satınalma Takvimi Veri Girişi'!$B$4:$AC$146,21,FALSE)<>"",VLOOKUP($B9,'Satınalma Takvimi Veri Girişi'!$B$4:$AC$146,21,FALSE),"") | AK9: =IF(VLOOKUP($B9,'Satınalma Takvimi Veri Girişi'!$B$4:$AC$146,22,FALSE)<>"",VLOOKUP($B9,'Satınalma Takvimi Veri Girişi'!$B$4:$AC$146,22,FALSE),"") | AL9: =IF(VLOOKUP($B9,'Satınalma Takvimi Veri Girişi'!$B$4:$AC$146,23,FALSE)<>"",VLOOKUP($B9,'Satınalma Takvimi Veri Girişi'!$B$4:$AC$146,23,FALSE),"") | AM9: =IF(VLOOKUP($B9,'Satınalma Takvimi Veri Girişi'!$B$4:$AC$146,24,FALSE)<>"",VLOOKUP($B9,'Satınalma Takvimi Veri Girişi'!$B$4:$AC$146,24,FALSE),"") | AN9: =IF(VLOOKUP($B9,'Satınalma Takvimi Veri Girişi'!$B$4:$AC$146,25,FALSE)<>"",VLOOKUP($B9,'Satınalma Takvimi Veri Girişi'!$B$4:$AC$146,25,FALSE),"") | AO9: =IF(VLOOKUP($B9,'Satınalma Takvimi Veri Girişi'!$B$4:$AC$146,26,FALSE)<>"",VLOOKUP($B9,'Satınalma Takvimi Veri Girişi'!$B$4:$AC$146,26,FALSE),"") | AP9: =IF(VLOOKUP($B9,'Satınalma Takvimi Veri Girişi'!$B$4:$AC$146,27,FALSE)<>"",VLOOKUP($B9,'Satınalma Takvimi Veri Girişi'!$B$4:$AC$146,27,FALSE),"") | AQ9: =IF(VLOOKUP($B9,'Satınalma Takvimi Veri Girişi'!$B$4:$AC$146,28,FALSE)<>"",VLOOKUP($B9,'Satınalma Takvimi Veri Girişi'!$B$4:$AC$146,28,FALSE),"")
B10: =Şablon!E9 -> IHL.3028.007/1 | C10: =VLOOKUP($B10,Şablon!$E$3:$Q$255,2,FALSE) -> 11.00.00 (M) DÖKME ÇİMENTO MALZEME | D10: =IF(VLOOKUP($B10,'Satınalma Takvimi Veri Girişi'!$B$4:$AC$146,3,FALSE)<>"",VLOOKUP($B10,'Satınalma Takvimi Veri Girişi'!$B$4:$AC$146,3,FALSE),"") | E10: =VLOOKUP($B10,Şablon!$E$3:$Q$255,3,FALSE) -> B KATEGORİ | F10: =VLOOKUP($B10,Şablon!$E$3:$Q$255,4,FALSE) -> İNŞ | G10: =VLOOKUP($B10,Şablon!$E$3:$Q$255,5,FALSE) -> 0 | H10: =IFERROR(L10-G10,"") | I10: =IFERROR(N10-J10,"") | J10: =IF(VLOOKUP($B10,'Satınalma Takvimi Veri Girişi'!$B$4:$AC$146,7,FALSE)<>"",VLOOKUP($B10,'Satınalma Takvimi Veri Girişi'!$B$4:$AC$146,7,FALSE),"") | K10: =VLOOKUP($B10,Şablon!$E$3:$Q$255,6,FALSE) -> 14 | L10: =IFERROR(P10-K10,"") | M10: =IFERROR(R10-N10,"") | N10: =IF(VLOOKUP($B10,'Satınalma Takvimi Veri Girişi'!$B$4:$AC$146,9,FALSE)<>"",VLOOKUP($B10,'Satınalma Takvimi Veri Girişi'!$B$4:$AC$146,9,FALSE),"") | O10: =VLOOKUP($B10,Şablon!$E$3:$Q$255,7,FALSE) -> 7 | P10: =IFERROR(T10-O10,"") | Q10: =IFERROR(V10-R10,"") | R10: =IF(VLOOKUP($B10,'Satınalma Takvimi Veri Girişi'!$B$4:$AC$146,11,FALSE)<>"",VLOOKUP($B10,'Satınalma Takvimi Veri Girişi'!$B$4:$AC$146,11,FALSE),"") | S10: =VLOOKUP($B10,Şablon!$E$3:$Q$255,8,FALSE) -> 21 | T10: =IFERROR(X10-S10,"") | U10: =IFERROR(Z10-V10,"") | V10: =IF(VLOOKUP($B10,'Satınalma Takvimi Veri Girişi'!$B$4:$AC$146,13,FALSE)<>"",VLOOKUP($B10,'Satınalma Takvimi Veri Girişi'!$B$4:$AC$146,13,FALSE),"") | W10: =VLOOKUP($B10,Şablon!$E$3:$Q$255,9,FALSE) -> 7 | X10: =IFERROR(AB10-W10,"") | Y10: =IFERROR(AD10-Z10,"") | Z10: =IF(VLOOKUP($B10,'Satınalma Takvimi Veri Girişi'!$B$4:$AC$146,15,FALSE)<>"",VLOOKUP($B10,'Satınalma Takvimi Veri Girişi'!$B$4:$AC$146,15,FALSE),"") | AA10: =VLOOKUP($B10,Şablon!$E$3:$Q$255,10,FALSE) -> 14 | AB10: =IFERROR(AF10-AA10,"") | AC10: =IFERROR(AH10-AD10,"") | AD10: =IF(VLOOKUP($B10,'Satınalma Takvimi Veri Girişi'!$B$4:$AC$146,17,FALSE)<>"",VLOOKUP($B10,'Satınalma Takvimi Veri Girişi'!$B$4:$AC$146,17,FALSE),"") | AE10: =(VLOOKUP($B10,Şablon!$E$3:$Q$255,11,FALSE)+VLOOKUP($B10,Şablon!$E$3:$Q$255,12,FALSE)) -> 7 | AF10: =IFERROR(AI10-AE10,"") | AG10: =IFERROR(AJ10-AH10,"") | AH10: =IF(VLOOKUP($B10,'Satınalma Takvimi Veri Girişi'!$B$4:$AC$146,19,FALSE)<>"",VLOOKUP($B10,'Satınalma Takvimi Veri Girişi'!$B$4:$AC$146,19,FALSE),"") | AI10: =IF(VLOOKUP($B10,'Satınalma Takvimi Veri Girişi'!$B$4:$AC$146,20,FALSE)<>"",VLOOKUP($B10,'Satınalma Takvimi Veri Girişi'!$B$4:$AC$146,20,FALSE),"") | AJ10: =IF(VLOOKUP($B10,'Satınalma Takvimi Veri Girişi'!$B$4:$AC$146,21,FALSE)<>"",VLOOKUP($B10,'Satınalma Takvimi Veri Girişi'!$B$4:$AC$146,21,FALSE),"") | AK10: =IF(VLOOKUP($B10,'Satınalma Takvimi Veri Girişi'!$B$4:$AC$146,22,FALSE)<>"",VLOOKUP($B10,'Satınalma Takvimi Veri Girişi'!$B$4:$AC$146,22,FALSE),"") | AL10: =IF(VLOOKUP($B10,'Satınalma Takvimi Veri Girişi'!$B$4:$AC$146,23,FALSE)<>"",VLOOKUP($B10,'Satınalma Takvimi Veri Girişi'!$B$4:$AC$146,23,FALSE),"") | AM10: =IF(VLOOKUP($B10,'Satınalma Takvimi Veri Girişi'!$B$4:$AC$146,24,FALSE)<>"",VLOOKUP($B10,'Satınalma Takvimi Veri Girişi'!$B$4:$AC$146,24,FALSE),"") | AN10: =IF(VLOOKUP($B10,'Satınalma Takvimi Veri Girişi'!$B$4:$AC$146,25,FALSE)<>"",VLOOKUP($B10,'Satınalma Takvimi Veri Girişi'!$B$4:$AC$146,25,FALSE),"") | AO10: =IF(VLOOKUP($B10,'Satınalma Takvimi Veri Girişi'!$B$4:$AC$146,26,FALSE)<>"",VLOOKUP($B10,'Satınalma Takvimi Veri Girişi'!$B$4:$AC$146,26,FALSE),"") | AP10: =IF(VLOOKUP($B10,'Satınalma Takvimi Veri Girişi'!$B$4:$AC$146,27,FALSE)<>"",VLOOKUP($B10,'Satınalma Takvimi Veri Girişi'!$B$4:$AC$146,27,FALSE),"") | AQ10: =IF(VLOOKUP($B10,'Satınalma Takvimi Veri Girişi'!$B$4:$AC$146,28,FALSE)<>"",VLOOKUP($B10,'Satınalma Takvimi Veri Girişi'!$B$4:$AC$146,28,FALSE),"")
B11: =Şablon!E10 -> IHL.3028.008/1 | C11: =VLOOKUP($B11,Şablon!$E$3:$Q$255,2,FALSE) -> 13.01.00 (M) HAZIR BETON MALZEME | D11: =IF(VLOOKUP($B11,'Satınalma Takvimi Veri Girişi'!$B$4:$AC$146,3,FALSE)<>"",VLOOKUP($B11,'Satınalma Takvimi Veri Girişi'!$B$4:$AC$146,3,FALSE),"") | E11: =VLOOKUP($B11,Şablon!$E$3:$Q$255,3,FALSE) -> B KATEGORİ | F11: =VLOOKUP($B11,Şablon!$E$3:$Q$255,4,FALSE) -> İNŞ | G11: =VLOOKUP($B11,Şablon!$E$3:$Q$255,5,FALSE) -> 0 | H11: =IFERROR(L11-G11,"") | I11: =IFERROR(N11-J11,"") | J11: =IF(VLOOKUP($B11,'Satınalma Takvimi Veri Girişi'!$B$4:$AC$146,7,FALSE)<>"",VLOOKUP($B11,'Satınalma Takvimi Veri Girişi'!$B$4:$AC$146,7,FALSE),"") | K11: =VLOOKUP($B11,Şablon!$E$3:$Q$255,6,FALSE) -> 14 | L11: =IFERROR(P11-K11,"") | M11: =IFERROR(R11-N11,"") | N11: =IF(VLOOKUP($B11,'Satınalma Takvimi Veri Girişi'!$B$4:$AC$146,9,FALSE)<>"",VLOOKUP($B11,'Satınalma Takvimi Veri Girişi'!$B$4:$AC$146,9,FALSE),"") | O11: =VLOOKUP($B11,Şablon!$E$3:$Q$255,7,FALSE) -> 7 | P11: =IFERROR(T11-O11,"") | Q11: =IFERROR(V11-R11,"") | R11: =IF(VLOOKUP($B11,'Satınalma Takvimi Veri Girişi'!$B$4:$AC$146,11,FALSE)<>"",VLOOKUP($B11,'Satınalma Takvimi Veri Girişi'!$B$4:$AC$146,11,FALSE),"") | S11: =VLOOKUP($B11,Şablon!$E$3:$Q$255,8,FALSE) -> 21 | T11: =IFERROR(X11-S11,"") | U11: =IFERROR(Z11-V11,"") | V11: =IF(VLOOKUP($B11,'Satınalma Takvimi Veri Girişi'!$B$4:$AC$146,13,FALSE)<>"",VLOOKUP($B11,'Satınalma Takvimi Veri Girişi'!$B$4:$AC$146,13,FALSE),"") | W11: =VLOOKUP($B11,Şablon!$E$3:$Q$255,9,FALSE) -> 7 | X11: =IFERROR(AB11-W11,"") | Y11: =IFERROR(AD11-Z11,"") | Z11: =IF(VLOOKUP($B11,'Satınalma Takvimi Veri Girişi'!$B$4:$AC$146,15,FALSE)<>"",VLOOKUP($B11,'Satınalma Takvimi Veri Girişi'!$B$4:$AC$146,15,FALSE),"") | AA11: =VLOOKUP($B11,Şablon!$E$3:$Q$255,10,FALSE) -> 14 | AB11: =IFERROR(AF11-AA11,"") | AC11: =IFERROR(AH11-AD11,"") | AD11: =IF(VLOOKUP($B11,'Satınalma Takvimi Veri Girişi'!$B$4:$AC$146,17,FALSE)<>"",VLOOKUP($B11,'Satınalma Takvimi Veri Girişi'!$B$4:$AC$146,17,FALSE),"") | AE11: =(VLOOKUP($B11,Şablon!$E$3:$Q$255,11,FALSE)+VLOOKUP($B11,Şablon!$E$3:$Q$255,12,FALSE)) -> 7 | AF11: =IFERROR(AI11-AE11,"") | AG11: =IFERROR(AJ11-AH11,"") | AH11: =IF(VLOOKUP($B11,'Satınalma Takvimi Veri Girişi'!$B$4:$AC$146,19,FALSE)<>"",VLOOKUP($B11,'Satınalma Takvimi Veri Girişi'!$B$4:$AC$146,19,FALSE),"") | AI11: =IF(VLOOKUP($B11,'Satınalma Takvimi Veri Girişi'!$B$4:$AC$146,20,FALSE)<>"",VLOOKUP($B11,'Satınalma Takvimi Veri Girişi'!$B$4:$AC$146,20,FALSE),"") | AJ11: =IF(VLOOKUP($B11,'Satınalma Takvimi Veri Girişi'!$B$4:$AC$146,21,FALSE)<>"",VLOOKUP($B11,'Satınalma Takvimi Veri Girişi'!$B$4:$AC$146,21,FALSE),"") | AK11: =IF(VLOOKUP($B11,'Satınalma Takvimi Veri Girişi'!$B$4:$AC$146,22,FALSE)<>"",VLOOKUP($B11,'Satınalma Takvimi Veri Girişi'!$B$4:$AC$146,22,FALSE),"") | AL11: =IF(VLOOKUP($B11,'Satınalma Takvimi Veri Girişi'!$B$4:$AC$146,23,FALSE)<>"",VLOOKUP($B11,'Satınalma Takvimi Veri Girişi'!$B$4:$AC$146,23,FALSE),"") | AM11: =IF(VLOOKUP($B11,'Satınalma Takvimi Veri Girişi'!$B$4:$AC$146,24,FALSE)<>"",VLOOKUP($B11,'Satınalma Takvimi Veri Girişi'!$B$4:$AC$146,24,FALSE),"") | AN11: =IF(VLOOKUP($B11,'Satınalma Takvimi Veri Girişi'!$B$4:$AC$146,25,FALSE)<>"",VLOOKUP($B11,'Satınalma Takvimi Veri Girişi'!$B$4:$AC$146,25,FALSE),"") | AO11: =IF(VLOOKUP($B11,'Satınalma Takvimi Veri Girişi'!$B$4:$AC$146,26,FALSE)<>"",VLOOKUP($B11,'Satınalma Takvimi Veri Girişi'!$B$4:$AC$146,26,FALSE),"") | AP11: =IF(VLOOKUP($B11,'Satınalma Takvimi Veri Girişi'!$B$4:$AC$146,27,FALSE)<>"",VLOOKUP($B11,'Satınalma Takvimi Veri Girişi'!$B$4:$AC$146,27,FALSE),"") | AQ11: =IF(VLOOKUP($B11,'Satınalma Takvimi Veri Girişi'!$B$4:$AC$146,28,FALSE)<>"",VLOOKUP($B11,'Satınalma Takvimi Veri Girişi'!$B$4:$AC$146,28,FALSE),"")
B12: =Şablon!E11 -> IHL.3028.009/1 | C12: =VLOOKUP($B12,Şablon!$E$3:$Q$255,2,FALSE) -> 09.02.00 HAFRİYAT | D12: =IF(VLOOKUP($B12,'Satınalma Takvimi Veri Girişi'!$B$4:$AC$146,3,FALSE)<>"",VLOOKUP($B12,'Satınalma Takvimi Veri Girişi'!$B$4:$AC$146,3,FALSE),"") | E12: =VLOOKUP($B12,Şablon!$E$3:$Q$255,3,FALSE) -> A KATEGORİ | F12: =VLOOKUP($B12,Şablon!$E$3:$Q$255,4,FALSE) -> İNŞ | G12: =VLOOKUP($B12,Şablon!$E$3:$Q$255,5,FALSE) -> 0 | H12: =IFERROR(L12-G12,"") | I12: =IFERROR(N12-J12,"") | J12: =IF(VLOOKUP($B12,'Satınalma Takvimi Veri Girişi'!$B$4:$AC$146,7,FALSE)<>"",VLOOKUP($B12,'Satınalma Takvimi Veri Girişi'!$B$4:$AC$146,7,FALSE),"") | K12: =VLOOKUP($B12,Şablon!$E$3:$Q$255,6,FALSE) -> 14 | L12: =IFERROR(P12-K12,"") | M12: =IFERROR(R12-N12,"") | N12: =IF(VLOOKUP($B12,'Satınalma Takvimi Veri Girişi'!$B$4:$AC$146,9,FALSE)<>"",VLOOKUP($B12,'Satınalma Takvimi Veri Girişi'!$B$4:$AC$146,9,FALSE),"") | O12: =VLOOKUP($B12,Şablon!$E$3:$Q$255,7,FALSE) -> 14 | P12: =IFERROR(T12-O12,"") | Q12: =IFERROR(V12-R12,"") | R12: =IF(VLOOKUP($B12,'Satınalma Takvimi Veri Girişi'!$B$4:$AC$146,11,FALSE)<>"",VLOOKUP($B12,'Satınalma Takvimi Veri Girişi'!$B$4:$AC$146,11,FALSE),"") | S12: =VLOOKUP($B12,Şablon!$E$3:$Q$255,8,FALSE) -> 28 | T12: =IFERROR(X12-S12,"") | U12: =IFERROR(Z12-V12,"") | V12: =IF(VLOOKUP($B12,'Satınalma Takvimi Veri Girişi'!$B$4:$AC$146,13,FALSE)<>"",VLOOKUP($B12,'Satınalma Takvimi Veri Girişi'!$B$4:$AC$146,13,FALSE),"") | W12: =VLOOKUP($B12,Şablon!$E$3:$Q$255,9,FALSE) -> 10 | X12: =IFERROR(AB12-W12,"") | Y12: =IFERROR(AD12-Z12,"") | Z12: =IF(VLOOKUP($B12,'Satınalma Takvimi Veri Girişi'!$B$4:$AC$146,15,FALSE)<>"",VLOOKUP($B12,'Satınalma Takvimi Veri Girişi'!$B$4:$AC$146,15,FALSE),"") | AA12: =VLOOKUP($B12,Şablon!$E$3:$Q$255,10,FALSE) -> 14 | AB12: =IFERROR(AF12-AA12,"") | AC12: =IFERROR(AH12-AD12,"") | AD12: =IF(VLOOKUP($B12,'Satınalma Takvimi Veri Girişi'!$B$4:$AC$146,17,FALSE)<>"",VLOOKUP($B12,'Satınalma Takvimi Veri Girişi'!$B$4:$AC$146,17,FALSE),"") | AE12: =(VLOOKUP($B12,Şablon!$E$3:$Q$255,11,FALSE)+VLOOKUP($B12,Şablon!$E$3:$Q$255,12,FALSE)) -> 7 | AF12: =IFERROR(AI12-AE12,"") | AG12: =IFERROR(AJ12-AH12,"") | AH12: =IF(VLOOKUP($B12,'Satınalma Takvimi Veri Girişi'!$B$4:$AC$146,19,FALSE)<>"",VLOOKUP($B12,'Satınalma Takvimi Veri Girişi'!$B$4:$AC$146,19,FALSE),"") | AI12: =IF(VLOOKUP($B12,'Satınalma Takvimi Veri Girişi'!$B$4:$AC$146,20,FALSE)<>"",VLOOKUP($B12,'Satınalma Takvimi Veri Girişi'!$B$4:$AC$146,20,FALSE),"") | AJ12: =IF(VLOOKUP($B12,'Satınalma Takvimi Veri Girişi'!$B$4:$AC$146,21,FALSE)<>"",VLOOKUP($B12,'Satınalma Takvimi Veri Girişi'!$B$4:$AC$146,21,FALSE),"") | AK12: =IF(VLOOKUP($B12,'Satınalma Takvimi Veri Girişi'!$B$4:$AC$146,22,FALSE)<>"",VLOOKUP($B12,'Satınalma Takvimi Veri Girişi'!$B$4:$AC$146,22,FALSE),"") | AL12: =IF(VLOOKUP($B12,'Satınalma Takvimi Veri Girişi'!$B$4:$AC$146,23,FALSE)<>"",VLOOKUP($B12,'Satınalma Takvimi Veri Girişi'!$B$4:$AC$146,23,FALSE),"") | AM12: =IF(VLOOKUP($B12,'Satınalma Takvimi Veri Girişi'!$B$4:$AC$146,24,FALSE)<>"",VLOOKUP($B12,'Satınalma Takvimi Veri Girişi'!$B$4:$AC$146,24,FALSE),"") | AN12: =IF(VLOOKUP($B12,'Satınalma Takvimi Veri Girişi'!$B$4:$AC$146,25,FALSE)<>"",VLOOKUP($B12,'Satınalma Takvimi Veri Girişi'!$B$4:$AC$146,25,FALSE),"") | AO12: =IF(VLOOKUP($B12,'Satınalma Takvimi Veri Girişi'!$B$4:$AC$146,26,FALSE)<>"",VLOOKUP($B12,'Satınalma Takvimi Veri Girişi'!$B$4:$AC$146,26,FALSE),"") | AP12: =IF(VLOOKUP($B12,'Satınalma Takvimi Veri Girişi'!$B$4:$AC$146,27,FALSE)<>"",VLOOKUP($B12,'Satınalma Takvimi Veri Girişi'!$B$4:$AC$146,27,FALSE),"") | AQ12: =IF(VLOOKUP($B12,'Satınalma Takvimi Veri Girişi'!$B$4:$AC$146,28,FALSE)<>"",VLOOKUP($B12,'Satınalma Takvimi Veri Girişi'!$B$4:$AC$146,28,FALSE),"")
